Workbook

Sheet INÍCIO
A1: NOMAD puffs — Controle de vendas
A2: VAPOR SEM FRONTEIRAS · Palmas – TO
A4: COMO USAR
A5: 1. VENDAS | B5: Lance cada item vendido em uma linha. Itens do mesmo pedido repetem o Nº do pedido, a data, o pagamento, a região e o entregador. A taxa de entrega só é cobrada na 1ª linha do pedido.
A6: 2. ENTREGADOR | B6: Cadastre os motoboys. No registro, digite só o Nº do pedido: data, motoboy, região, modelos e valores aparecem sozinhos. Atualize o status da entrega.
A7: 3. MERCADORIA | B7: Digite as entradas de estoque (compras) por sabor. Vendido e estoque atual são automáticos.
A8: 4. VALOR | B8: Preço de venda de cada modelo (vem do catálogo). Preencha o custo para ver a margem.
A9: 5. MAPA | B9: Taxas de entrega por quadra/bairro de Palmas e o desempenho de cada região.
A10: 6. RESUMO | B10: Painel com os totais: faturamento, pedidos, ticket médio, PIX x cartão, modelos e regiões.
A12: CORES
A13: Texto azul / fundo amarelo | B13: Célula para você digitar ou escolher na lista.
A14: Texto verde | B14: Valor puxado de outra aba (não digite).
A15: Texto preto | B15: Fórmula / cálculo automático (não digite).
A17: EXEMPLO | B17: A aba VENDAS traz um pedido de exemplo (Nº 1, marcado EXEMPLO). Apague as linhas 5 e 6 de VENDAS e a 1ª linha do registro de entregas (coluna H) em ENTREGADOR antes de começar a usar.
A18: FONTE DOS PREÇOS | B18: Catálogo NOMAD puffs (docs/catalogo.pdf), informado pelos sócios em 01/10/2026.
A19: GOOGLE SHEETS | B19: Arquivo > Importar > Fazer upload > Substituir planilha. Fórmulas e listas continuam funcionando.

Sheet RESUMO
A1: RESUMO
A2: Atualiza sozinho conforme VENDAS é preenchida
A4: Indicador | B4: Valor | D4: Forma de pagamento | E4: Pedidos | F4: Valor (R$)
A5: Pedidos | B5: =SUM(VENDAS!O5:O1004) | D5: PIX | E5: =SUMIFS(VENDAS!$O$5:$O$1004,VENDAS!$I$5:$I$1004,D5) | F5: =SUMIFS(VENDAS!$L$5:$L$1004,VENDAS!$I$5:$I$1004,D5)
A6: Unidades vendidas | B6: =SUM(VENDAS!F5:F1004) | D6: Cartão de débito | E6: =SUMIFS(VENDAS!$O$5:$O$1004,VENDAS!$I$5:$I$1004,D6) | F6: =SUMIFS(VENDAS!$L$5:$L$1004,VENDAS!$I$5:$I$1004,D6)
A7: Vendas em produtos | B7: =SUM(VENDAS!H5:H1004) | D7: Cartão de crédito | E7: =SUMIFS(VENDAS!$O$5:$O$1004,VENDAS!$I$5:$I$1004,D7) | F7: =SUMIFS(VENDAS!$L$5:$L$1004,VENDAS!$I$5:$I$1004,D7)
A8: Taxas de entrega | B8: =SUM(VENDAS!K5:K1004) | D8: Cartão (débito + crédito) | E8: =E6+E7 | F8: =F6+F7
A9: Faturamento total | B9: =B7+B8 | D9: TOTAL | E9: =E5+E8 | F9: =F5+F8
A10: Ticket médio por pedido | B10: =IF(B5=0,0,B9/B5) | D10: Sem forma de pagamento | E10: =B5-E9 | F10: =B9-F9
A13: Modelo | B13: Unidades | D13: Vendas (R$)
A14: V55 | B14: =SUMIFS(VENDAS!$F$5:$F$1004,VENDAS!$D$5:$D$1004,A14) | D14: =SUMIFS(VENDAS!$H$5:$H$1004,VENDAS!$D$5:$D$1004,A14)
A15: V155 | B15: =SUMIFS(VENDAS!$F$5:$F$1004,VENDAS!$D$5:$D$1004,A15) | D15: =SUMIFS(VENDAS!$H$5:$H$1004,VENDAS!$D$5:$D$1004,A15)
A16: V400 Mix Slim | B16: =SUMIFS(VENDAS!$F$5:$F$1004,VENDAS!$D$5:$D$1004,A16) | D16: =SUMIFS(VENDAS!$H$5:$H$1004,VENDAS!$D$5:$D$1004,A16)
A17: Elfbar Pro 40K | B17: =SUMIFS(VENDAS!$F$5:$F$1004,VENDAS!$D$5:$D$1004,A17) | D17: =SUMIFS(VENDAS!$H$5:$H$1004,VENDAS!$D$5:$D$1004,A17)
A18: TOTAL | B18: =SUM(B14:B17) | D18: =SUM(D14:D17)
A19: Conferência: TOTAL de modelos deve bater com 'Vendas em produtos'.

Sheet VENDAS
A1: VENDAS
A2: Uma linha por item vendido · totais somam sozinhos
F3: =SUM(F5:F1004) | H3: =SUM(H5:H1004) | J3: TOTAIS ▸ | K3: =SUM(K5:K1004) | L3: =SUM(L5:L1004) | O3: =SUM(O5:O1004)
A4: Nº pedido | B4: Data | C4: Produto (modelo - sabor) | D4: Modelo | E4: Sabor | F4: Qtd | G4: Valor unit. (R$) | H4: Subtotal (R$) | I4: Pagamento | J4: Região de entrega | K4: Taxa entrega (R$) | L4: Total (R$) | M4: Entregador | N4: Endereço / observação | O4: Pedido único
A5: 1 | B5: 46296 | C5: V155 - Grape Ice | D5: =IF(C5="","",INDEX(MERCADORIA!$B$5:$B$22,MATCH(C5,MERCADORIA!$A$5:$A$22,0))) | E5: =IF(C5="","",INDEX(MERCADORIA!$C$5:$C$22,MATCH(C5,MERCADORIA!$A$5:$A$22,0))) | F5: 2 | G5: =IF(D5="","",INDEX(VALOR!$B$5:$B$8,MATCH(D5,VALOR!$A$5:$A$8,0))) | H5: =IF(OR(G5="",F5=""),0,F5*G5) | I5: PIX | J5: Quadras 300 Norte a 600 Norte | K5: =IF(OR(O5=0,J5=""),0,INDEX(MAPA!$C$5:$C$14,MATCH(J5,MAPA!$A$5:$A$14,0))) | L5: =H5+K5 | M5: Motoboy 1 | N5: EXEMPLO — apagar | O5: =IF(A5="",0,IF(COUNTIF($A$5:A5,A5)=1,1,0))
A6: 1 | B6: 46296 | C6: Elfbar Pro 40K - Pink Lemonade | D6: =IF(C6="","",INDEX(MERCADORIA!$B$5:$B$22,MATCH(C6,MERCADORIA!$A$5:$A$22,0))) | E6: =IF(C6="","",INDEX(MERCADORIA!$C$5:$C$22,MATCH(C6,MERCADORIA!$A$5:$A$22,0))) | F6: 1 | G6: =IF(D6="","",INDEX(VALOR!$B$5:$B$8,MATCH(D6,VALOR!$A$5:$A$8,0))) | H6: =IF(OR(G6="",F6=""),0,F6*G6) | I6: PIX | J6: Quadras 300 Norte a 600 Norte | K6: =IF(OR(O6=0,J6=""),0,INDEX(MAPA!$C$5:$C$14,MATCH(J6,MAPA!$A$5:$A$14,0))) | L6: =H6+K6 | M6: Motoboy 1 | N6: EXEMPLO — apagar | O6: =IF(A6="",0,IF(COUNTIF($A$5:A6,A6)=1,1,0))
D7: =IF(C7="","",INDEX(MERCADORIA!$B$5:$B$22,MATCH(C7,MERCADORIA!$A$5:$A$22,0))) | E7: =IF(C7="","",INDEX(MERCADORIA!$C$5:$C$22,MATCH(C7,MERCADORIA!$A$5:$A$22,0))) | G7: =IF(D7="","",INDEX(VALOR!$B$5:$B$8,MATCH(D7,VALOR!$A$5:$A$8,0))) | H7: =IF(OR(G7="",F7=""),0,F7*G7) | K7: =IF(OR(O7=0,J7=""),0,INDEX(MAPA!$C$5:$C$14,MATCH(J7,MAPA!$A$5:$A$14,0))) | L7: =H7+K7 | O7: =IF(A7="",0,IF(COUNTIF($A$5:A7,A7)=1,1,0))
D8: =IF(C8="","",INDEX(MERCADORIA!$B$5:$B$22,MATCH(C8,MERCADORIA!$A$5:$A$22,0))) | E8: =IF(C8="","",INDEX(MERCADORIA!$C$5:$C$22,MATCH(C8,MERCADORIA!$A$5:$A$22,0))) | G8: =IF(D8="","",INDEX(VALOR!$B$5:$B$8,MATCH(D8,VALOR!$A$5:$A$8,0))) | H8: =IF(OR(G8="",F8=""),0,F8*G8) | K8: =IF(OR(O8=0,J8=""),0,INDEX(MAPA!$C$5:$C$14,MATCH(J8,MAPA!$A$5:$A$14,0))) | L8: =H8+K8 | O8: =IF(A8="",0,IF(COUNTIF($A$5:A8,A8)=1,1,0))
D9: =IF(C9="","",INDEX(MERCADORIA!$B$5:$B$22,MATCH(C9,MERCADORIA!$A$5:$A$22,0))) | E9: =IF(C9="","",INDEX(MERCADORIA!$C$5:$C$22,MATCH(C9,MERCADORIA!$A$5:$A$22,0))) | G9: =IF(D9="","",INDEX(VALOR!$B$5:$B$8,MATCH(D9,VALOR!$A$5:$A$8,0))) | H9: =IF(OR(G9="",F9=""),0,F9*G9) | K9: =IF(OR(O9=0,J9=""),0,INDEX(MAPA!$C$5:$C$14,MATCH(J9,MAPA!$A$5:$A$14,0))) | L9: =H9+K9 | O9: =IF(A9="",0,IF(COUNTIF($A$5:A9,A9)=1,1,0))
D10: =IF(C10="","",INDEX(MERCADORIA!$B$5:$B$22,MATCH(C10,MERCADORIA!$A$5:$A$22,0))) | E10: =IF(C10="","",INDEX(MERCADORIA!$C$5:$C$22,MATCH(C10,MERCADORIA!$A$5:$A$22,0))) | G10: =IF(D10="","",INDEX(VALOR!$B$5:$B$8,MATCH(D10,VALOR!$A$5:$A$8,0))) | H10: =IF(OR(G10="",F10=""),0,F10*G10) | K10: =IF(OR(O10=0,J10=""),0,INDEX(MAPA!$C$5:$C$14,MATCH(J10,MAPA!$A$5:$A$14,0))) | L10: =H10+K10 | O10: =IF(A10="",0,IF(COUNTIF($A$5:A10,A10)=1,1,0))
D11: =IF(C11="","",INDEX(MERCADORIA!$B$5:$B$22,MATCH(C11,MERCADORIA!$A$5:$A$22,0))) | E11: =IF(C11="","",INDEX(MERCADORIA!$C$5:$C$22,MATCH(C11,MERCADORIA!$A$5:$A$22,0))) | G11: =IF(D11="","",INDEX(VALOR!$B$5:$B$8,MATCH(D11,VALOR!$A$5:$A$8,0))) | H11: =IF(OR(G11="",F11=""),0,F11*G11) | K11: =IF(OR(O11=0,J11=""),0,INDEX(MAPA!$C$5:$C$14,MATCH(J11,MAPA!$A$5:$A$14,0))) | L11: =H11+K11 | O11: =IF(A11="",0,IF(COUNTIF($A$5:A11,A11)=1,1,0))
D12: =IF(C12="","",INDEX(MERCADORIA!$B$5:$B$22,MATCH(C12,MERCADORIA!$A$5:$A$22,0))) | E12: =IF(C12="","",INDEX(MERCADORIA!$C$5:$C$22,MATCH(C12,MERCADORIA!$A$5:$A$22,0))) | G12: =IF(D12="","",INDEX(VALOR!$B$5:$B$8,MATCH(D12,VALOR!$A$5:$A$8,0))) | H12: =IF(OR(G12="",F12=""),0,F12*G12) | K12: =IF(OR(O12=0,J12=""),0,INDEX(MAPA!$C$5:$C$14,MATCH(J12,MAPA!$A$5:$A$14,0))) | L12: =H12+K12 | O12: =IF(A12="",0,IF(COUNTIF($A$5:A12,A12)=1,1,0))
D13: =IF(C13="","",INDEX(MERCADORIA!$B$5:$B$22,MATCH(C13,MERCADORIA!$A$5:$A$22,0))) | E13: =IF(C13="","",INDEX(MERCADORIA!$C$5:$C$22,MATCH(C13,MERCADORIA!$A$5:$A$22,0))) | G13: =IF(D13="","",INDEX(VALOR!$B$5:$B$8,MATCH(D13,VALOR!$A$5:$A$8,0))) | H13: =IF(OR(G13="",F13=""),0,F13*G13) | K13: =IF(OR(O13=0,J13=""),0,INDEX(MAPA!$C$5:$C$14,MATCH(J13,MAPA!$A$5:$A$14,0))) | L13: =H13+K13 | O13: =IF(A13="",0,IF(COUNTIF($A$5:A13,A13)=1,1,0))
D14: =IF(C14="","",INDEX(MERCADORIA!$B$5:$B$22,MATCH(C14,MERCADORIA!$A$5:$A$22,0))) | E14: =IF(C14="","",INDEX(MERCADORIA!$C$5:$C$22,MATCH(C14,MERCADORIA!$A$5:$A$22,0))) | G14: =IF(D14="","",INDEX(VALOR!$B$5:$B$8,MATCH(D14,VALOR!$A$5:$A$8,0))) | H14: =IF(OR(G14="",F14=""),0,F14*G14) | K14: =IF(OR(O14=0,J14=""),0,INDEX(MAPA!$C$5:$C$14,MATCH(J14,MAPA!$A$5:$A$14,0))) | L14: =H14+K14 | O14: =IF(A14="",0,IF(COUNTIF($A$5:A14,A14)=1,1,0))
D15: =IF(C15="","",INDEX(MERCADORIA!$B$5:$B$22,MATCH(C15,MERCADORIA!$A$5:$A$22,0))) | E15: =IF(C15="","",INDEX(MERCADORIA!$C$5:$C$22,MATCH(C15,MERCADORIA!$A$5:$A$22,0))) | G15: =IF(D15="","",INDEX(VALOR!$B$5:$B$8,MATCH(D15,VALOR!$A$5:$A$8,0))) | H15: =IF(OR(G15="",F15=""),0,F15*G15) | K15: =IF(OR(O15=0,J15=""),0,INDEX(MAPA!$C$5:$C$14,MATCH(J15,MAPA!$A$5:$A$14,0))) | L15: =H15+K15 | O15: =IF(A15="",0,IF(COUNTIF($A$5:A15,A15)=1,1,0))
D16: =IF(C16="","",INDEX(MERCADORIA!$B$5:$B$22,MATCH(C16,MERCADORIA!$A$5:$A$22,0))) | E16: =IF(C16="","",INDEX(MERCADORIA!$C$5:$C$22,MATCH(C16,MERCADORIA!$A$5:$A$22,0))) | G16: =IF(D16="","",INDEX(VALOR!$B$5:$B$8,MATCH(D16,VALOR!$A$5:$A$8,0))) | H16: =IF(OR(G16="",F16=""),0,F16*G16) | K16: =IF(OR(O16=0,J16=""),0,INDEX(MAPA!$C$5:$C$14,MATCH(J16,MAPA!$A$5:$A$14,0))) | L16: =H16+K16 | O16: =IF(A16="",0,IF(COUNTIF($A$5:A16,A16)=1,1,0))
D17: =IF(C17="","",INDEX(MERCADORIA!$B$5:$B$22,MATCH(C17,MERCADORIA!$A$5:$A$22,0))) | E17: =IF(C17="","",INDEX(MERCADORIA!$C$5:$C$22,MATCH(C17,MERCADORIA!$A$5:$A$22,0))) | G17: =IF(D17="","",INDEX(VALOR!$B$5:$B$8,MATCH(D17,VALOR!$A$5:$A$8,0))) | H17: =IF(OR(G17="",F17=""),0,F17*G17) | K17: =IF(OR(O17=0,J17=""),0,INDEX(MAPA!$C$5:$C$14,MATCH(J17,MAPA!$A$5:$A$14,0))) | L17: =H17+K17 | O17: =IF(A17="",0,IF(COUNTIF($A$5:A17,A17)=1,1,0))
D18: =IF(C18="","",INDEX(MERCADORIA!$B$5:$B$22,MATCH(C18,MERCADORIA!$A$5:$A$22,0))) | E18: =IF(C18="","",INDEX(MERCADORIA!$C$5:$C$22,MATCH(C18,MERCADORIA!$A$5:$A$22,0))) | G18: =IF(D18="","",INDEX(VALOR!$B$5:$B$8,MATCH(D18,VALOR!$A$5:$A$8,0))) | H18: =IF(OR(G18="",F18=""),0,F18*G18) | K18: =IF(OR(O18=0,J18=""),0,INDEX(MAPA!$C$5:$C$14,MATCH(J18,MAPA!$A$5:$A$14,0))) | L18: =H18+K18 | O18: =IF(A18="",0,IF(COUNTIF($A$5:A18,A18)=1,1,0))
... D1004: =IF(C1004="","",INDEX(MERCADORIA!$B$5:$B$22,MATCH(C1004,MERCADORIA!$A$5:$A$22,0))) | E1004: =IF(C1004="","",INDEX(MERCADORIA!$C$5:$C$22,MATCH(C1004,MERCADORIA!$A$5:$A$22,0))) | G1004: =IF(D1004="","",INDEX(VALOR!$B$5:$B$8,MATCH(D1004,VALOR!$A$5:$A$8,0))) | H1004: =IF(OR(G1004="",F1004=""),0,F1004*G1004) | K1004: =IF(OR(O1004=0,J1004=""),0,INDEX(MAPA!$C$5:$C$14,MATCH(J1004,MAPA!$A$5:$A$14,0))) | L1004: =H1004+K1004 | O1004: =IF(A1004="",0,IF(COUNTIF($A$5:A1004,A1004)=1,1,0))

Sheet MERCADORIA
A1: MERCADORIA
A2: Estoque por modelo e sabor — vendido e saldo são automáticos
A4: Produto (código) | B4: Modelo | C4: Sabor | D4: Entradas (un.) | E4: Vendido (un.) | F4: Estoque atual (un.) | G4: Valor unit. (R$) | H4: Valor em estoque (R$) | I4: Faturado (R$)
A5: =B5&" - "&C5 | B5: V55 | C5: Pineapple Ice | E5: =SUMIFS(VENDAS!$F$5:$F$1004,VENDAS!$C$5:$C$1004,A5) | F5: =N(D5)-E5 | G5: =INDEX(VALOR!$B$5:$B$8,MATCH(B5,VALOR!$A$5:$A$8,0)) | H5: =MAX(F5,0)*G5 | I5: =SUMIFS(VENDAS!$H$5:$H$1004,VENDAS!$C$5:$C$1004,A5)
A6: =B6&" - "&C6 | B6: V55 | C6: Uva Ice | E6: =SUMIFS(VENDAS!$F$5:$F$1004,VENDAS!$C$5:$C$1004,A6) | F6: =N(D6)-E6 | G6: =INDEX(VALOR!$B$5:$B$8,MATCH(B6,VALOR!$A$5:$A$8,0)) | H6: =MAX(F6,0)*G6 | I6: =SUMIFS(VENDAS!$H$5:$H$1004,VENDAS!$C$5:$C$1004,A6)
A7: =B7&" - "&C7 | B7: V55 | C7: Icy Mint | E7: =SUMIFS(VENDAS!$F$5:$F$1004,VENDAS!$C$5:$C$1004,A7) | F7: =N(D7)-E7 | G7: =INDEX(VALOR!$B$5:$B$8,MATCH(B7,VALOR!$A$5:$A$8,0)) | H7: =MAX(F7,0)*G7 | I7: =SUMIFS(VENDAS!$H$5:$H$1004,VENDAS!$C$5:$C$1004,A7)
A8: =B8&" - "&C8 | B8: V155 | C8: Pineapple Ice | E8: =SUMIFS(VENDAS!$F$5:$F$1004,VENDAS!$C$5:$C$1004,A8) | F8: =N(D8)-E8 | G8: =INDEX(VALOR!$B$5:$B$8,MATCH(B8,VALOR!$A$5:$A$8,0)) | H8: =MAX(F8,0)*G8 | I8: =SUMIFS(VENDAS!$H$5:$H$1004,VENDAS!$C$5:$C$1004,A8)
A9: =B9&" - "&C9 | B9: V155 | C9: Menthol | E9: =SUMIFS(VENDAS!$F$5:$F$1004,VENDAS!$C$5:$C$1004,A9) | F9: =N(D9)-E9 | G9: =INDEX(VALOR!$B$5:$B$8,MATCH(B9,VALOR!$A$5:$A$8,0)) | H9: =MAX(F9,0)*G9 | I9: =SUMIFS(VENDAS!$H$5:$H$1004,VENDAS!$C$5:$C$1004,A9)
A10: =B10&" - "&C10 | B10: V155 | C10: Grape Ice | E10: =SUMIFS(VENDAS!$F$5:$F$1004,VENDAS!$C$5:$C$1004,A10) | F10: =N(D10)-E10 | G10: =INDEX(VALOR!$B$5:$B$8,MATCH(B10,VALOR!$A$5:$A$8,0)) | H10: =MAX(F10,0)*G10 | I10: =SUMIFS(VENDAS!$H$5:$H$1004,VENDAS!$C$5:$C$1004,A10)
A11: =B11&" - "&C11 | B11: V155 | C11: Watermelon Ice | E11: =SUMIFS(VENDAS!$F$5:$F$1004,VENDAS!$C$5:$C$1004,A11) | F11: =N(D11)-E11 | G11: =INDEX(VALOR!$B$5:$B$8,MATCH(B11,VALOR!$A$5:$A$8,0)) | H11: =MAX(F11,0)*G11 | I11: =SUMIFS(VENDAS!$H$5:$H$1004,VENDAS!$C$5:$C$1004,A11)
A12: =B12&" - "&C12 | B12: V155 | C12: Icy Mint | E12: =SUMIFS(VENDAS!$F$5:$F$1004,VENDAS!$C$5:$C$1004,A12) | F12: =N(D12)-E12 | G12: =INDEX(VALOR!$B$5:$B$8,MATCH(B12,VALOR!$A$5:$A$8,0)) | H12: =MAX(F12,0)*G12 | I12: =SUMIFS(VENDAS!$H$5:$H$1004,VENDAS!$C$5:$C$1004,A12)
A13: =B13&" - "&C13 | B13: V400 Mix Slim | C13: Icy Mint + Peach Grape | E13: =SUMIFS(VENDAS!$F$5:$F$1004,VENDAS!$C$5:$C$1004,A13) | F13: =N(D13)-E13 | G13: =INDEX(VALOR!$B$5:$B$8,MATCH(B13,VALOR!$A$5:$A$8,0)) | H13: =MAX(F13,0)*G13 | I13: =SUMIFS(VENDAS!$H$5:$H$1004,VENDAS!$C$5:$C$1004,A13)
A14: =B14&" - "&C14 | B14: V400 Mix Slim | C14: Menthol + Mighty Melon | E14: =SUMIFS(VENDAS!$F$5:$F$1004,VENDAS!$C$5:$C$1004,A14) | F14: =N(D14)-E14 | G14: =INDEX(VALOR!$B$5:$B$8,MATCH(B14,VALOR!$A$5:$A$8,0)) | H14: =MAX(F14,0)*G14 | I14: =SUMIFS(VENDAS!$H$5:$H$1004,VENDAS!$C$5:$C$1004,A14)
A15: =B15&" - "&C15 | B15: V400 Mix Slim | C15: Mango + Passion Fruit Guava | E15: =SUMIFS(VENDAS!$F$5:$F$1004,VENDAS!$C$5:$C$1004,A15) | F15: =N(D15)-E15 | G15: =INDEX(VALOR!$B$5:$B$8,MATCH(B15,VALOR!$A$5:$A$8,0)) | H15: =MAX(F15,0)*G15 | I15: =SUMIFS(VENDAS!$H$5:$H$1004,VENDAS!$C$5:$C$1004,A15)
A16: =B16&" - "&C16 | B16: V400 Mix Slim | C16: Strawberry Grape Ice + Kiwi Watermelon | E16: =SUMIFS(VENDAS!$F$5:$F$1004,VENDAS!$C$5:$C$1004,A16) | F16: =N(D16)-E16 | G16: =INDEX(VALOR!$B$5:$B$8,MATCH(B16,VALOR!$A$5:$A$8,0)) | H16: =MAX(F16,0)*G16 | I16: =SUMIFS(VENDAS!$H$5:$H$1004,VENDAS!$C$5:$C$1004,A16)
... A22: =B22&" - "&C22 | B22: Elfbar Pro 40K | C22: Tropical Baja | E22: =SUMIFS(VENDAS!$F$5:$F$1004,VENDAS!$C$5:$C$1004,A22) | F22: =N(D22)-E22 | G22: =INDEX(VALOR!$B$5:$B$8,MATCH(B22,VALOR!$A$5:$A$8,0)) | H22: =MAX(F22,0)*G22 | I22: =SUMIFS(VENDAS!$H$5:$H$1004,VENDAS!$C$5:$C$1004,A22)
A23: TOTAL | D23: =SUM(D5:D22) | E23: =SUM(E5:E22) | F23: =SUM(F5:F22) | H23: =SUM(H5:H22) | I23: =SUM(I5:I22)
A25: Vermelho = estoque negativo (vendeu mais do que entrou). Amarelo = 3 unidades ou menos.

Sheet VALOR
A1: VALOR
A2: Preço de cada unidade por modelo
A4: Modelo | B4: Preço de venda (R$/un.) | C4: Custo (R$/un.) | D4: Lucro (R$/un.) | E4: Margem
A5: V55 | B5: 85 | D5: =IF(C5="","",B5-C5) | E5: =IF(OR(C5="",B5=0),"",D5/B5)
A6: V155 | B6: 110 | D6: =IF(C6="","",B6-C6) | E6: =IF(OR(C6="",B6=0),"",D6/B6)
A7: V400 Mix Slim | B7: 140 | D7: =IF(C7="","",B7-C7) | E7: =IF(OR(C7="",B7=0),"",D7/B7)
A8: Elfbar Pro 40K | B8: 140 | D8: =IF(C8="","",B8-C8) | E8: =IF(OR(C8="",B8=0),"",D8/B8)

Sheet ENTREGADOR
A1: ENTREGADOR
A2: Motoboys, entregas e modelos entregues
A4: Motoboy | B4: Telefone | C4: Pedidos entregues | D4: Unidades | H4: Nº pedido | I4: Data | J4: Motoboy | K4: Região | L4: Unidades | M4: V55 | N4: V155 | O4: V400 Mix Slim | P4: Elfbar Pro 40K | Q4: Valor pedido (R$) | R4: Taxa entrega (R$) | S4: Status | T4: Horário entrega
A5: Motoboy 1 | C5: =IF(A5="","",COUNTIFS($J$5:$J$504,A5,$S$5:$S$504,"Entregue")) | D5: =IF(A5="","",SUMIFS($L$5:$L$504,$J$5:$J$504,A5,$S$5:$S$504,"Entregue")) | H5: 1 | I5: =IF(H5="","",IFERROR(INDEX(VENDAS!$B$5:$B$1004,MATCH(H5,VENDAS!$A$5:$A$1004,0)),"não lançado")) | J5: =IF(H5="","",IFERROR(INDEX(VENDAS!$M$5:$M$1004,MATCH(H5,VENDAS!$A$5:$A$1004,0))&"","")) | K5: =IF(H5="","",IFERROR(INDEX(VENDAS!$J$5:$J$1004,MATCH(H5,VENDAS!$A$5:$A$1004,0))&"","")) | L5: =IF(H5="","",SUMIFS(VENDAS!$F$5:$F$1004,VENDAS!$A$5:$A$1004,H5)) | M5: =IF(H5="","",SUMIFS(VENDAS!$F$5:$F$1004,VENDAS!$A$5:$A$1004,H5,VENDAS!$D$5:$D$1004,M$4)) | N5: =IF(H5="","",SUMIFS(VENDAS!$F$5:$F$1004,VENDAS!$A$5:$A$1004,H5,VENDAS!$D$5:$D$1004,N$4)) | O5: =IF(H5="","",SUMIFS(VENDAS!$F$5:$F$1004,VENDAS!$A$5:$A$1004,H5,VENDAS!$D$5:$D$1004,O$4)) | P5: =IF(H5="","",SUMIFS(VENDAS!$F$5:$F$1004,VENDAS!$A$5:$A$1004,H5,VENDAS!$D$5:$D$1004,P$4)) | Q5: =IF(H5="","",SUMIFS(VENDAS!$H$5:$H$1004,VENDAS!$A$5:$A$1004,H5)) | R5: =IF(H5="","",SUMIFS(VENDAS!$K$5:$K$1004,VENDAS!$A$5:$A$1004,H5)) | S5: Entregue
A6: Motoboy 2 | C6: =IF(A6="","",COUNTIFS($J$5:$J$504,A6,$S$5:$S$504,"Entregue")) | D6: =IF(A6="","",SUMIFS($L$5:$L$504,$J$5:$J$504,A6,$S$5:$S$504,"Entregue")) | I6: =IF(H6="","",IFERROR(INDEX(VENDAS!$B$5:$B$1004,MATCH(H6,VENDAS!$A$5:$A$1004,0)),"não lançado")) | J6: =IF(H6="","",IFERROR(INDEX(VENDAS!$M$5:$M$1004,MATCH(H6,VENDAS!$A$5:$A$1004,0))&"","")) | K6: =IF(H6="","",IFERROR(INDEX(VENDAS!$J$5:$J$1004,MATCH(H6,VENDAS!$A$5:$A$1004,0))&"","")) | L6: =IF(H6="","",SUMIFS(VENDAS!$F$5:$F$1004,VENDAS!$A$5:$A$1004,H6)) | M6: =IF(H6="","",SUMIFS(VENDAS!$F$5:$F$1004,VENDAS!$A$5:$A$1004,H6,VENDAS!$D$5:$D$1004,M$4)) | N6: =IF(H6="","",SUMIFS(VENDAS!$F$5:$F$1004,VENDAS!$A$5:$A$1004,H6,VENDAS!$D$5:$D$1004,N$4)) | O6: =IF(H6="","",SUMIFS(VENDAS!$F$5:$F$1004,VENDAS!$A$5:$A$1004,H6,VENDAS!$D$5:$D$1004,O$4)) | P6: =IF(H6="","",SUMIFS(VENDAS!$F$5:$F$1004,VENDAS!$A$5:$A$1004,H6,VENDAS!$D$5:$D$1004,P$4)) | Q6: =IF(H6="","",SUMIFS(VENDAS!$H$5:$H$1004,VENDAS!$A$5:$A$1004,H6)) | R6: =IF(H6="","",SUMIFS(VENDAS!$K$5:$K$1004,VENDAS!$A$5:$A$1004,H6))
A7: Motoboy 3 | C7: =IF(A7="","",COUNTIFS($J$5:$J$504,A7,$S$5:$S$504,"Entregue")) | D7: =IF(A7="","",SUMIFS($L$5:$L$504,$J$5:$J$504,A7,$S$5:$S$504,"Entregue")) | I7: =IF(H7="","",IFERROR(INDEX(VENDAS!$B$5:$B$1004,MATCH(H7,VENDAS!$A$5:$A$1004,0)),"não lançado")) | J7: =IF(H7="","",IFERROR(INDEX(VENDAS!$M$5:$M$1004,MATCH(H7,VENDAS!$A$5:$A$1004,0))&"","")) | K7: =IF(H7="","",IFERROR(INDEX(VENDAS!$J$5:$J$1004,MATCH(H7,VENDAS!$A$5:$A$1004,0))&"","")) | L7: =IF(H7="","",SUMIFS(VENDAS!$F$5:$F$1004,VENDAS!$A$5:$A$1004,H7)) | M7: =IF(H7="","",SUMIFS(VENDAS!$F$5:$F$1004,VENDAS!$A$5:$A$1004,H7,VENDAS!$D$5:$D$1004,M$4)) | N7: =IF(H7="","",SUMIFS(VENDAS!$F$5:$F$1004,VENDAS!$A$5:$A$1004,H7,VENDAS!$D$5:$D$1004,N$4)) | O7: =IF(H7="","",SUMIFS(VENDAS!$F$5:$F$1004,VENDAS!$A$5:$A$1004,H7,VENDAS!$D$5:$D$1004,O$4)) | P7: =IF(H7="","",SUMIFS(VENDAS!$F$5:$F$1004,VENDAS!$A$5:$A$1004,H7,VENDAS!$D$5:$D$1004,P$4)) | Q7: =IF(H7="","",SUMIFS(VENDAS!$H$5:$H$1004,VENDAS!$A$5:$A$1004,H7)) | R7: =IF(H7="","",SUMIFS(VENDAS!$K$5:$K$1004,VENDAS!$A$5:$A$1004,H7))
C8: =IF(A8="","",COUNTIFS($J$5:$J$504,A8,$S$5:$S$504,"Entregue")) | D8: =IF(A8="","",SUMIFS($L$5:$L$504,$J$5:$J$504,A8,$S$5:$S$504,"Entregue")) | I8: =IF(H8="","",IFERROR(INDEX(VENDAS!$B$5:$B$1004,MATCH(H8,VENDAS!$A$5:$A$1004,0)),"não lançado")) | J8: =IF(H8="","",IFERROR(INDEX(VENDAS!$M$5:$M$1004,MATCH(H8,VENDAS!$A$5:$A$1004,0))&"","")) | K8: =IF(H8="","",IFERROR(INDEX(VENDAS!$J$5:$J$1004,MATCH(H8,VENDAS!$A$5:$A$1004,0))&"","")) | L8: =IF(H8="","",SUMIFS(VENDAS!$F$5:$F$1004,VENDAS!$A$5:$A$1004,H8)) | M8: =IF(H8="","",SUMIFS(VENDAS!$F$5:$F$1004,VENDAS!$A$5:$A$1004,H8,VENDAS!$D$5:$D$1004,M$4)) | N8: =IF(H8="","",SUMIFS(VENDAS!$F$5:$F$1004,VENDAS!$A$5:$A$1004,H8,VENDAS!$D$5:$D$1004,N$4)) | O8: =IF(H8="","",SUMIFS(VENDAS!$F$5:$F$1004,VENDAS!$A$5:$A$1004,H8,VENDAS!$D$5:$D$1004,O$4)) | P8: =IF(H8="","",SUMIFS(VENDAS!$F$5:$F$1004,VENDAS!$A$5:$A$1004,H8,VENDAS!$D$5:$D$1004,P$4)) | Q8: =IF(H8="","",SUMIFS(VENDAS!$H$5:$H$1004,VENDAS!$A$5:$A$1004,H8)) | R8: =IF(H8="","",SUMIFS(VENDAS!$K$5:$K$1004,VENDAS!$A$5:$A$1004,H8))
C9: =IF(A9="","",COUNTIFS($J$5:$J$504,A9,$S$5:$S$504,"Entregue")) | D9: =IF(A9="","",SUMIFS($L$5:$L$504,$J$5:$J$504,A9,$S$5:$S$504,"Entregue")) | I9: =IF(H9="","",IFERROR(INDEX(VENDAS!$B$5:$B$1004,MATCH(H9,VENDAS!$A$5:$A$1004,0)),"não lançado")) | J9: =IF(H9="","",IFERROR(INDEX(VENDAS!$M$5:$M$1004,MATCH(H9,VENDAS!$A$5:$A$1004,0))&"","")) | K9: =IF(H9="","",IFERROR(INDEX(VENDAS!$J$5:$J$1004,MATCH(H9,VENDAS!$A$5:$A$1004,0))&"","")) | L9: =IF(H9="","",SUMIFS(VENDAS!$F$5:$F$1004,VENDAS!$A$5:$A$1004,H9)) | M9: =IF(H9="","",SUMIFS(VENDAS!$F$5:$F$1004,VENDAS!$A$5:$A$1004,H9,VENDAS!$D$5:$D$1004,M$4)) | N9: =IF(H9="","",SUMIFS(VENDAS!$F$5:$F$1004,VENDAS!$A$5:$A$1004,H9,VENDAS!$D$5:$D$1004,N$4)) | O9: =IF(H9="","",SUMIFS(VENDAS!$F$5:$F$1004,VENDAS!$A$5:$A$1004,H9,VENDAS!$D$5:$D$1004,O$4)) | P9: =IF(H9="","",SUMIFS(VENDAS!$F$5:$F$1004,VENDAS!$A$5:$A$1004,H9,VENDAS!$D$5:$D$1004,P$4)) | Q9: =IF(H9="","",SUMIFS(VENDAS!$H$5:$H$1004,VENDAS!$A$5:$A$1004,H9)) | R9: =IF(H9="","",SUMIFS(VENDAS!$K$5:$K$1004,VENDAS!$A$5:$A$1004,H9))
C10: =IF(A10="","",COUNTIFS($J$5:$J$504,A10,$S$5:$S$504,"Entregue")) | D10: =IF(A10="","",SUMIFS($L$5:$L$504,$J$5:$J$504,A10,$S$5:$S$504,"Entregue")) | I10: =IF(H10="","",IFERROR(INDEX(VENDAS!$B$5:$B$1004,MATCH(H10,VENDAS!$A$5:$A$1004,0)),"não lançado")) | J10: =IF(H10="","",IFERROR(INDEX(VENDAS!$M$5:$M$1004,MATCH(H10,VENDAS!$A$5:$A$1004,0))&"","")) | K10: =IF(H10="","",IFERROR(INDEX(VENDAS!$J$5:$J$1004,MATCH(H10,VENDAS!$A$5:$A$1004,0))&"","")) | L10: =IF(H10="","",SUMIFS(VENDAS!$F$5:$F$1004,VENDAS!$A$5:$A$1004,H10)) | M10: =IF(H10="","",SUMIFS(VENDAS!$F$5:$F$1004,VENDAS!$A$5:$A$1004,H10,VENDAS!$D$5:$D$1004,M$4)) | N10: =IF(H10="","",SUMIFS(VENDAS!$F$5:$F$1004,VENDAS!$A$5:$A$1004,H10,VENDAS!$D$5:$D$1004,N$4)) | O10: =IF(H10="","",SUMIFS(VENDAS!$F$5:$F$1004,VENDAS!$A$5:$A$1004,H10,VENDAS!$D$5:$D$1004,O$4)) | P10: =IF(H10="","",SUMIFS(VENDAS!$F$5:$F$1004,VENDAS!$A$5:$A$1004,H10,VENDAS!$D$5:$D$1004,P$4)) | Q10: =IF(H10="","",SUMIFS(VENDAS!$H$5:$H$1004,VENDAS!$A$5:$A$1004,H10)) | R10: =IF(H10="","",SUMIFS(VENDAS!$K$5:$K$1004,VENDAS!$A$5:$A$1004,H10))
C11: =IF(A11="","",COUNTIFS($J$5:$J$504,A11,$S$5:$S$504,"Entregue")) | D11: =IF(A11="","",SUMIFS($L$5:$L$504,$J$5:$J$504,A11,$S$5:$S$504,"Entregue")) | I11: =IF(H11="","",IFERROR(INDEX(VENDAS!$B$5:$B$1004,MATCH(H11,VENDAS!$A$5:$A$1004,0)),"não lançado")) | J11: =IF(H11="","",IFERROR(INDEX(VENDAS!$M$5:$M$1004,MATCH(H11,VENDAS!$A$5:$A$1004,0))&"","")) | K11: =IF(H11="","",IFERROR(INDEX(VENDAS!$J$5:$J$1004,MATCH(H11,VENDAS!$A$5:$A$1004,0))&"","")) | L11: =IF(H11="","",SUMIFS(VENDAS!$F$5:$F$1004,VENDAS!$A$5:$A$1004,H11)) | M11: =IF(H11="","",SUMIFS(VENDAS!$F$5:$F$1004,VENDAS!$A$5:$A$1004,H11,VENDAS!$D$5:$D$1004,M$4)) | N11: =IF(H11="","",SUMIFS(VENDAS!$F$5:$F$1004,VENDAS!$A$5:$A$1004,H11,VENDAS!$D$5:$D$1004,N$4)) | O11: =IF(H11="","",SUMIFS(VENDAS!$F$5:$F$1004,VENDAS!$A$5:$A$1004,H11,VENDAS!$D$5:$D$1004,O$4)) | P11: =IF(H11="","",SUMIFS(VENDAS!$F$5:$F$1004,VENDAS!$A$5:$A$1004,H11,VENDAS!$D$5:$D$1004,P$4)) | Q11: =IF(H11="","",SUMIFS(VENDAS!$H$5:$H$1004,VENDAS!$A$5:$A$1004,H11)) | R11: =IF(H11="","",SUMIFS(VENDAS!$K$5:$K$1004,VENDAS!$A$5:$A$1004,H11))
C12: =IF(A12="","",COUNTIFS($J$5:$J$504,A12,$S$5:$S$504,"Entregue")) | D12: =IF(A12="","",SUMIFS($L$5:$L$504,$J$5:$J$504,A12,$S$5:$S$504,"Entregue")) | I12: =IF(H12="","",IFERROR(INDEX(VENDAS!$B$5:$B$1004,MATCH(H12,VENDAS!$A$5:$A$1004,0)),"não lançado")) | J12: =IF(H12="","",IFERROR(INDEX(VENDAS!$M$5:$M$1004,MATCH(H12,VENDAS!$A$5:$A$1004,0))&"","")) | K12: =IF(H12="","",IFERROR(INDEX(VENDAS!$J$5:$J$1004,MATCH(H12,VENDAS!$A$5:$A$1004,0))&"","")) | L12: =IF(H12="","",SUMIFS(VENDAS!$F$5:$F$1004,VENDAS!$A$5:$A$1004,H12)) | M12: =IF(H12="","",SUMIFS(VENDAS!$F$5:$F$1004,VENDAS!$A$5:$A$1004,H12,VENDAS!$D$5:$D$1004,M$4)) | N12: =IF(H12="","",SUMIFS(VENDAS!$F$5:$F$1004,VENDAS!$A$5:$A$1004,H12,VENDAS!$D$5:$D$1004,N$4)) | O12: =IF(H12="","",SUMIFS(VENDAS!$F$5:$F$1004,VENDAS!$A$5:$A$1004,H12,VENDAS!$D$5:$D$1004,O$4)) | P12: =IF(H12="","",SUMIFS(VENDAS!$F$5:$F$1004,VENDAS!$A$5:$A$1004,H12,VENDAS!$D$5:$D$1004,P$4)) | Q12: =IF(H12="","",SUMIFS(VENDAS!$H$5:$H$1004,VENDAS!$A$5:$A$1004,H12)) | R12: =IF(H12="","",SUMIFS(VENDAS!$K$5:$K$1004,VENDAS!$A$5:$A$1004,H12))
C13: =IF(A13="","",COUNTIFS($J$5:$J$504,A13,$S$5:$S$504,"Entregue")) | D13: =IF(A13="","",SUMIFS($L$5:$L$504,$J$5:$J$504,A13,$S$5:$S$504,"Entregue")) | I13: =IF(H13="","",IFERROR(INDEX(VENDAS!$B$5:$B$1004,MATCH(H13,VENDAS!$A$5:$A$1004,0)),"não lançado")) | J13: =IF(H13="","",IFERROR(INDEX(VENDAS!$M$5:$M$1004,MATCH(H13,VENDAS!$A$5:$A$1004,0))&"","")) | K13: =IF(H13="","",IFERROR(INDEX(VENDAS!$J$5:$J$1004,MATCH(H13,VENDAS!$A$5:$A$1004,0))&"","")) | L13: =IF(H13="","",SUMIFS(VENDAS!$F$5:$F$1004,VENDAS!$A$5:$A$1004,H13)) | M13: =IF(H13="","",SUMIFS(VENDAS!$F$5:$F$1004,VENDAS!$A$5:$A$1004,H13,VENDAS!$D$5:$D$1004,M$4)) | N13: =IF(H13="","",SUMIFS(VENDAS!$F$5:$F$1004,VENDAS!$A$5:$A$1004,H13,VENDAS!$D$5:$D$1004,N$4)) | O13: =IF(H13="","",SUMIFS(VENDAS!$F$5:$F$1004,VENDAS!$A$5:$A$1004,H13,VENDAS!$D$5:$D$1004,O$4)) | P13: =IF(H13="","",SUMIFS(VENDAS!$F$5:$F$1004,VENDAS!$A$5:$A$1004,H13,VENDAS!$D$5:$D$1004,P$4)) | Q13: =IF(H13="","",SUMIFS(VENDAS!$H$5:$H$1004,VENDAS!$A$5:$A$1004,H13)) | R13: =IF(H13="","",SUMIFS(VENDAS!$K$5:$K$1004,VENDAS!$A$5:$A$1004,H13))
C14: =IF(A14="","",COUNTIFS($J$5:$J$504,A14,$S$5:$S$504,"Entregue")) | D14: =IF(A14="","",SUMIFS($L$5:$L$504,$J$5:$J$504,A14,$S$5:$S$504,"Entregue")) | I14: =IF(H14="","",IFERROR(INDEX(VENDAS!$B$5:$B$1004,MATCH(H14,VENDAS!$A$5:$A$1004,0)),"não lançado")) | J14: =IF(H14="","",IFERROR(INDEX(VENDAS!$M$5:$M$1004,MATCH(H14,VENDAS!$A$5:$A$1004,0))&"","")) | K14: =IF(H14="","",IFERROR(INDEX(VENDAS!$J$5:$J$1004,MATCH(H14,VENDAS!$A$5:$A$1004,0))&"","")) | L14: =IF(H14="","",SUMIFS(VENDAS!$F$5:$F$1004,VENDAS!$A$5:$A$1004,H14)) | M14: =IF(H14="","",SUMIFS(VENDAS!$F$5:$F$1004,VENDAS!$A$5:$A$1004,H14,VENDAS!$D$5:$D$1004,M$4)) | N14: =IF(H14="","",SUMIFS(VENDAS!$F$5:$F$1004,VENDAS!$A$5:$A$1004,H14,VENDAS!$D$5:$D$1004,N$4)) | O14: =IF(H14="","",SUMIFS(VENDAS!$F$5:$F$1004,VENDAS!$A$5:$A$1004,H14,VENDAS!$D$5:$D$1004,O$4)) | P14: =IF(H14="","",SUMIFS(VENDAS!$F$5:$F$1004,VENDAS!$A$5:$A$1004,H14,VENDAS!$D$5:$D$1004,P$4)) | Q14: =IF(H14="","",SUMIFS(VENDAS!$H$5:$H$1004,VENDAS!$A$5:$A$1004,H14)) | R14: =IF(H14="","",SUMIFS(VENDAS!$K$5:$K$1004,VENDAS!$A$5:$A$1004,H14))
I15: =IF(H15="","",IFERROR(INDEX(VENDAS!$B$5:$B$1004,MATCH(H15,VENDAS!$A$5:$A$1004,0)),"não lançado")) | J15: =IF(H15="","",IFERROR(INDEX(VENDAS!$M$5:$M$1004,MATCH(H15,VENDAS!$A$5:$A$1004,0))&"","")) | K15: =IF(H15="","",IFERROR(INDEX(VENDAS!$J$5:$J$1004,MATCH(H15,VENDAS!$A$5:$A$1004,0))&"","")) | L15: =IF(H15="","",SUMIFS(VENDAS!$F$5:$F$1004,VENDAS!$A$5:$A$1004,H15)) | M15: =IF(H15="","",SUMIFS(VENDAS!$F$5:$F$1004,VENDAS!$A$5:$A$1004,H15,VENDAS!$D$5:$D$1004,M$4)) | N15: =IF(H15="","",SUMIFS(VENDAS!$F$5:$F$1004,VENDAS!$A$5:$A$1004,H15,VENDAS!$D$5:$D$1004,N$4)) | O15: =IF(H15="","",SUMIFS(VENDAS!$F$5:$F$1004,VENDAS!$A$5:$A$1004,H15,VENDAS!$D$5:$D$1004,O$4)) | P15: =IF(H15="","",SUMIFS(VENDAS!$F$5:$F$1004,VENDAS!$A$5:$A$1004,H15,VENDAS!$D$5:$D$1004,P$4)) | Q15: =IF(H15="","",SUMIFS(VENDAS!$H$5:$H$1004,VENDAS!$A$5:$A$1004,H15)) | R15: =IF(H15="","",SUMIFS(VENDAS!$K$5:$K$1004,VENDAS!$A$5:$A$1004,H15))
A16: Troque 'Motoboy 1/2/3' pelos nomes reais — as listas de VENDAS se atualizam. | I16: =IF(H16="","",IFERROR(INDEX(VENDAS!$B$5:$B$1004,MATCH(H16,VENDAS!$A$5:$A$1004,0)),"não lançado")) | J16: =IF(H16="","",IFERROR(INDEX(VENDAS!$M$5:$M$1004,MATCH(H16,VENDAS!$A$5:$A$1004,0))&"","")) | K16: =IF(H16="","",IFERROR(INDEX(VENDAS!$J$5:$J$1004,MATCH(H16,VENDAS!$A$5:$A$1004,0))&"","")) | L16: =IF(H16="","",SUMIFS(VENDAS!$F$5:$F$1004,VENDAS!$A$5:$A$1004,H16)) | M16: =IF(H16="","",SUMIFS(VENDAS!$F$5:$F$1004,VENDAS!$A$5:$A$1004,H16,VENDAS!$D$5:$D$1004,M$4)) | N16: =IF(H16="","",SUMIFS(VENDAS!$F$5:$F$1004,VENDAS!$A$5:$A$1004,H16,VENDAS!$D$5:$D$1004,N$4)) | O16: =IF(H16="","",SUMIFS(VENDAS!$F$5:$F$1004,VENDAS!$A$5:$A$1004,H16,VENDAS!$D$5:$D$1004,O$4)) | P16: =IF(H16="","",SUMIFS(VENDAS!$F$5:$F$1004,VENDAS!$A$5:$A$1004,H16,VENDAS!$D$5:$D$1004,P$4)) | Q16: =IF(H16="","",SUMIFS(VENDAS!$H$5:$H$1004,VENDAS!$A$5:$A$1004,H16)) | R16: =IF(H16="","",SUMIFS(VENDAS!$K$5:$K$1004,VENDAS!$A$5:$A$1004,H16))
I17: =IF(H17="","",IFERROR(INDEX(VENDAS!$B$5:$B$1004,MATCH(H17,VENDAS!$A$5:$A$1004,0)),"não lançado")) | J17: =IF(H17="","",IFERROR(INDEX(VENDAS!$M$5:$M$1004,MATCH(H17,VENDAS!$A$5:$A$1004,0))&"","")) | K17: =IF(H17="","",IFERROR(INDEX(VENDAS!$J$5:$J$1004,MATCH(H17,VENDAS!$A$5:$A$1004,0))&"","")) | L17: =IF(H17="","",SUMIFS(VENDAS!$F$5:$F$1004,VENDAS!$A$5:$A$1004,H17)) | M17: =IF(H17="","",SUMIFS(VENDAS!$F$5:$F$1004,VENDAS!$A$5:$A$1004,H17,VENDAS!$D$5:$D$1004,M$4)) | N17: =IF(H17="","",SUMIFS(VENDAS!$F$5:$F$1004,VENDAS!$A$5:$A$1004,H17,VENDAS!$D$5:$D$1004,N$4)) | O17: =IF(H17="","",SUMIFS(VENDAS!$F$5:$F$1004,VENDAS!$A$5:$A$1004,H17,VENDAS!$D$5:$D$1004,O$4)) | P17: =IF(H17="","",SUMIFS(VENDAS!$F$5:$F$1004,VENDAS!$A$5:$A$1004,H17,VENDAS!$D$5:$D$1004,P$4)) | Q17: =IF(H17="","",SUMIFS(VENDAS!$H$5:$H$1004,VENDAS!$A$5:$A$1004,H17)) | R17: =IF(H17="","",SUMIFS(VENDAS!$K$5:$K$1004,VENDAS!$A$5:$A$1004,H17))
A18: UNIDADES ENTREGUES POR MODELO | I18: =IF(H18="","",IFERROR(INDEX(VENDAS!$B$5:$B$1004,MATCH(H18,VENDAS!$A$5:$A$1004,0)),"não lançado")) | J18: =IF(H18="","",IFERROR(INDEX(VENDAS!$M$5:$M$1004,MATCH(H18,VENDAS!$A$5:$A$1004,0))&"","")) | K18: =IF(H18="","",IFERROR(INDEX(VENDAS!$J$5:$J$1004,MATCH(H18,VENDAS!$A$5:$A$1004,0))&"","")) | L18: =IF(H18="","",SUMIFS(VENDAS!$F$5:$F$1004,VENDAS!$A$5:$A$1004,H18)) | M18: =IF(H18="","",SUMIFS(VENDAS!$F$5:$F$1004,VENDAS!$A$5:$A$1004,H18,VENDAS!$D$5:$D$1004,M$4)) | N18: =IF(H18="","",SUMIFS(VENDAS!$F$5:$F$1004,VENDAS!$A$5:$A$1004,H18,VENDAS!$D$5:$D$1004,N$4)) | O18: =IF(H18="","",SUMIFS(VENDAS!$F$5:$F$1004,VENDAS!$A$5:$A$1004,H18,VENDAS!$D$5:$D$1004,O$4)) | P18: =IF(H18="","",SUMIFS(VENDAS!$F$5:$F$1004,VENDAS!$A$5:$A$1004,H18,VENDAS!$D$5:$D$1004,P$4)) | Q18: =IF(H18="","",SUMIFS(VENDAS!$H$5:$H$1004,VENDAS!$A$5:$A$1004,H18)) | R18: =IF(H18="","",SUMIFS(VENDAS!$K$5:$K$1004,VENDAS!$A$5:$A$1004,H18))
A19: Motoboy | B19: V55 | C19: V155 | D19: V400 Mix Slim | E19: Elfbar Pro 40K | F19: Taxas (R$) | I19: =IF(H19="","",IFERROR(INDEX(VENDAS!$B$5:$B$1004,MATCH(H19,VENDAS!$A$5:$A$1004,0)),"não lançado")) | J19: =IF(H19="","",IFERROR(INDEX(VENDAS!$M$5:$M$1004,MATCH(H19,VENDAS!$A$5:$A$1004,0))&"","")) | K19: =IF(H19="","",IFERROR(INDEX(VENDAS!$J$5:$J$1004,MATCH(H19,VENDAS!$A$5:$A$1004,0))&"","")) | L19: =IF(H19="","",SUMIFS(VENDAS!$F$5:$F$1004,VENDAS!$A$5:$A$1004,H19)) | M19: =IF(H19="","",SUMIFS(VENDAS!$F$5:$F$1004,VENDAS!$A$5:$A$1004,H19,VENDAS!$D$5:$D$1004,M$4)) | N19: =IF(H19="","",SUMIFS(VENDAS!$F$5:$F$1004,VENDAS!$A$5:$A$1004,H19,VENDAS!$D$5:$D$1004,N$4)) | O19: =IF(H19="","",SUMIFS(VENDAS!$F$5:$F$1004,VENDAS!$A$5:$A$1004,H19,VENDAS!$D$5:$D$1004,O$4)) | P19: =IF(H19="","",SUMIFS(VENDAS!$F$5:$F$1004,VENDAS!$A$5:$A$1004,H19,VENDAS!$D$5:$D$1004,P$4)) | Q19: =IF(H19="","",SUMIFS(VENDAS!$H$5:$H$1004,VENDAS!$A$5:$A$1004,H19)) | R19: =IF(H19="","",SUMIFS(VENDAS!$K$5:$K$1004,VENDAS!$A$5:$A$1004,H19))
A20: =IF(A5="","",A5) | B20: =IF($A20="","",SUMIFS($M$5:$M$504,$J$5:$J$504,$A20,$S$5:$S$504,"Entregue")) | C20: =IF($A20="","",SUMIFS($N$5:$N$504,$J$5:$J$504,$A20,$S$5:$S$504,"Entregue")) | D20: =IF($A20="","",SUMIFS($O$5:$O$504,$J$5:$J$504,$A20,$S$5:$S$504,"Entregue")) | E20: =IF($A20="","",SUMIFS($P$5:$P$504,$J$5:$J$504,$A20,$S$5:$S$504,"Entregue")) | F20: =IF($A20="","",SUMIFS($R$5:$R$504,$J$5:$J$504,$A20,$S$5:$S$504,"Entregue")) | I20: =IF(H20="","",IFERROR(INDEX(VENDAS!$B$5:$B$1004,MATCH(H20,VENDAS!$A$5:$A$1004,0)),"não lançado")) | J20: =IF(H20="","",IFERROR(INDEX(VENDAS!$M$5:$M$1004,MATCH(H20,VENDAS!$A$5:$A$1004,0))&"","")) | K20: =IF(H20="","",IFERROR(INDEX(VENDAS!$J$5:$J$1004,MATCH(H20,VENDAS!$A$5:$A$1004,0))&"","")) | L20: =IF(H20="","",SUMIFS(VENDAS!$F$5:$F$1004,VENDAS!$A$5:$A$1004,H20)) | M20: =IF(H20="","",SUMIFS(VENDAS!$F$5:$F$1004,VENDAS!$A$5:$A$1004,H20,VENDAS!$D$5:$D$1004,M$4)) | N20: =IF(H20="","",SUMIFS(VENDAS!$F$5:$F$1004,VENDAS!$A$5:$A$1004,H20,VENDAS!$D$5:$D$1004,N$4)) | O20: =IF(H20="","",SUMIFS(VENDAS!$F$5:$F$1004,VENDAS!$A$5:$A$1004,H20,VENDAS!$D$5:$D$1004,O$4)) | P20: =IF(H20="","",SUMIFS(VENDAS!$F$5:$F$1004,VENDAS!$A$5:$A$1004,H20,VENDAS!$D$5:$D$1004,P$4)) | Q20: =IF(H20="","",SUMIFS(VENDAS!$H$5:$H$1004,VENDAS!$A$5:$A$1004,H20)) | R20: =IF(H20="","",SUMIFS(VENDAS!$K$5:$K$1004,VENDAS!$A$5:$A$1004,H20))
A21: =IF(A6="","",A6) | B21: =IF($A21="","",SUMIFS($M$5:$M$504,$J$5:$J$504,$A21,$S$5:$S$504,"Entregue")) | C21: =IF($A21="","",SUMIFS($N$5:$N$504,$J$5:$J$504,$A21,$S$5:$S$504,"Entregue")) | D21: =IF($A21="","",SUMIFS($O$5:$O$504,$J$5:$J$504,$A21,$S$5:$S$504,"Entregue")) | E21: =IF($A21="","",SUMIFS($P$5:$P$504,$J$5:$J$504,$A21,$S$5:$S$504,"Entregue")) | F21: =IF($A21="","",SUMIFS($R$5:$R$504,$J$5:$J$504,$A21,$S$5:$S$504,"Entregue")) | I21: =IF(H21="","",IFERROR(INDEX(VENDAS!$B$5:$B$1004,MATCH(H21,VENDAS!$A$5:$A$1004,0)),"não lançado")) | J21: =IF(H21="","",IFERROR(INDEX(VENDAS!$M$5:$M$1004,MATCH(H21,VENDAS!$A$5:$A$1004,0))&"","")) | K21: =IF(H21="","",IFERROR(INDEX(VENDAS!$J$5:$J$1004,MATCH(H21,VENDAS!$A$5:$A$1004,0))&"","")) | L21: =IF(H21="","",SUMIFS(VENDAS!$F$5:$F$1004,VENDAS!$A$5:$A$1004,H21)) | M21: =IF(H21="","",SUMIFS(VENDAS!$F$5:$F$1004,VENDAS!$A$5:$A$1004,H21,VENDAS!$D$5:$D$1004,M$4)) | N21: =IF(H21="","",SUMIFS(VENDAS!$F$5:$F$1004,VENDAS!$A$5:$A$1004,H21,VENDAS!$D$5:$D$1004,N$4)) | O21: =IF(H21="","",SUMIFS(VENDAS!$F$5:$F$1004,VENDAS!$A$5:$A$1004,H21,VENDAS!$D$5:$D$1004,O$4)) | P21: =IF(H21="","",SUMIFS(VENDAS!$F$5:$F$1004,VENDAS!$A$5:$A$1004,H21,VENDAS!$D$5:$D$1004,P$4)) | Q21: =IF(H21="","",SUMIFS(VENDAS!$H$5:$H$1004,VENDAS!$A$5:$A$1004,H21)) | R21: =IF(H21="","",SUMIFS(VENDAS!$K$5:$K$1004,VENDAS!$A$5:$A$1004,H21))
A22: =IF(A7="","",A7) | B22: =IF($A22="","",SUMIFS($M$5:$M$504,$J$5:$J$504,$A22,$S$5:$S$504,"Entregue")) | C22: =IF($A22="","",SUMIFS($N$5:$N$504,$J$5:$J$504,$A22,$S$5:$S$504,"Entregue")) | D22: =IF($A22="","",SUMIFS($O$5:$O$504,$J$5:$J$504,$A22,$S$5:$S$504,"Entregue")) | E22: =IF($A22="","",SUMIFS($P$5:$P$504,$J$5:$J$504,$A22,$S$5:$S$504,"Entregue")) | F22: =IF($A22="","",SUMIFS($R$5:$R$504,$J$5:$J$504,$A22,$S$5:$S$504,"Entregue")) | I22: =IF(H22="","",IFERROR(INDEX(VENDAS!$B$5:$B$1004,MATCH(H22,VENDAS!$A$5:$A$1004,0)),"não lançado")) | J22: =IF(H22="","",IFERROR(INDEX(VENDAS!$M$5:$M$1004,MATCH(H22,VENDAS!$A$5:$A$1004,0))&"","")) | K22: =IF(H22="","",IFERROR(INDEX(VENDAS!$J$5:$J$1004,MATCH(H22,VENDAS!$A$5:$A$1004,0))&"","")) | L22: =IF(H22="","",SUMIFS(VENDAS!$F$5:$F$1004,VENDAS!$A$5:$A$1004,H22)) | M22: =IF(H22="","",SUMIFS(VENDAS!$F$5:$F$1004,VENDAS!$A$5:$A$1004,H22,VENDAS!$D$5:$D$1004,M$4)) | N22: =IF(H22="","",SUMIFS(VENDAS!$F$5:$F$1004,VENDAS!$A$5:$A$1004,H22,VENDAS!$D$5:$D$1004,N$4)) | O22: =IF(H22="","",SUMIFS(VENDAS!$F$5:$F$1004,VENDAS!$A$5:$A$1004,H22,VENDAS!$D$5:$D$1004,O$4)) | P22: =IF(H22="","",SUMIFS(VENDAS!$F$5:$F$1004,VENDAS!$A$5:$A$1004,H22,VENDAS!$D$5:$D$1004,P$4)) | Q22: =IF(H22="","",SUMIFS(VENDAS!$H$5:$H$1004,VENDAS!$A$5:$A$1004,H22)) | R22: =IF(H22="","",SUMIFS(VENDAS!$K$5:$K$1004,VENDAS!$A$5:$A$1004,H22))
A23: =IF(A8="","",A8) | B23: =IF($A23="","",SUMIFS($M$5:$M$504,$J$5:$J$504,$A23,$S$5:$S$504,"Entregue")) | C23: =IF($A23="","",SUMIFS($N$5:$N$504,$J$5:$J$504,$A23,$S$5:$S$504,"Entregue")) | D23: =IF($A23="","",SUMIFS($O$5:$O$504,$J$5:$J$504,$A23,$S$5:$S$504,"Entregue")) | E23: =IF($A23="","",SUMIFS($P$5:$P$504,$J$5:$J$504,$A23,$S$5:$S$504,"Entregue")) | F23: =IF($A23="","",SUMIFS($R$5:$R$504,$J$5:$J$504,$A23,$S$5:$S$504,"Entregue")) | I23: =IF(H23="","",IFERROR(INDEX(VENDAS!$B$5:$B$1004,MATCH(H23,VENDAS!$A$5:$A$1004,0)),"não lançado")) | J23: =IF(H23="","",IFERROR(INDEX(VENDAS!$M$5:$M$1004,MATCH(H23,VENDAS!$A$5:$A$1004,0))&"","")) | K23: =IF(H23="","",IFERROR(INDEX(VENDAS!$J$5:$J$1004,MATCH(H23,VENDAS!$A$5:$A$1004,0))&"","")) | L23: =IF(H23="","",SUMIFS(VENDAS!$F$5:$F$1004,VENDAS!$A$5:$A$1004,H23)) | M23: =IF(H23="","",SUMIFS(VENDAS!$F$5:$F$1004,VENDAS!$A$5:$A$1004,H23,VENDAS!$D$5:$D$1004,M$4)) | N23: =IF(H23="","",SUMIFS(VENDAS!$F$5:$F$1004,VENDAS!$A$5:$A$1004,H23,VENDAS!$D$5:$D$1004,N$4)) | O23: =IF(H23="","",SUMIFS(VENDAS!$F$5:$F$1004,VENDAS!$A$5:$A$1004,H23,VENDAS!$D$5:$D$1004,O$4)) | P23: =IF(H23="","",SUMIFS(VENDAS!$F$5:$F$1004,VENDAS!$A$5:$A$1004,H23,VENDAS!$D$5:$D$1004,P$4)) | Q23: =IF(H23="","",SUMIFS(VENDAS!$H$5:$H$1004,VENDAS!$A$5:$A$1004,H23)) | R23: =IF(H23="","",SUMIFS(VENDAS!$K$5:$K$1004,VENDAS!$A$5:$A$1004,H23))
A24: =IF(A9="","",A9) | B24: =IF($A24="","",SUMIFS($M$5:$M$504,$J$5:$J$504,$A24,$S$5:$S$504,"Entregue")) | C24: =IF($A24="","",SUMIFS($N$5:$N$504,$J$5:$J$504,$A24,$S$5:$S$504,"Entregue")) | D24: =IF($A24="","",SUMIFS($O$5:$O$504,$J$5:$J$504,$A24,$S$5:$S$504,"Entregue")) | E24: =IF($A24="","",SUMIFS($P$5:$P$504,$J$5:$J$504,$A24,$S$5:$S$504,"Entregue")) | F24: =IF($A24="","",SUMIFS($R$5:$R$504,$J$5:$J$504,$A24,$S$5:$S$504,"Entregue")) | I24: =IF(H24="","",IFERROR(INDEX(VENDAS!$B$5:$B$1004,MATCH(H24,VENDAS!$A$5:$A$1004,0)),"não lançado")) | J24: =IF(H24="","",IFERROR(INDEX(VENDAS!$M$5:$M$1004,MATCH(H24,VENDAS!$A$5:$A$1004,0))&"","")) | K24: =IF(H24="","",IFERROR(INDEX(VENDAS!$J$5:$J$1004,MATCH(H24,VENDAS!$A$5:$A$1004,0))&"","")) | L24: =IF(H24="","",SUMIFS(VENDAS!$F$5:$F$1004,VENDAS!$A$5:$A$1004,H24)) | M24: =IF(H24="","",SUMIFS(VENDAS!$F$5:$F$1004,VENDAS!$A$5:$A$1004,H24,VENDAS!$D$5:$D$1004,M$4)) | N24: =IF(H24="","",SUMIFS(VENDAS!$F$5:$F$1004,VENDAS!$A$5:$A$1004,H24,VENDAS!$D$5:$D$1004,N$4)) | O24: =IF(H24="","",SUMIFS(VENDAS!$F$5:$F$1004,VENDAS!$A$5:$A$1004,H24,VENDAS!$D$5:$D$1004,O$4)) | P24: =IF(H24="","",SUMIFS(VENDAS!$F$5:$F$1004,VENDAS!$A$5:$A$1004,H24,VENDAS!$D$5:$D$1004,P$4)) | Q24: =IF(H24="","",SUMIFS(VENDAS!$H$5:$H$1004,VENDAS!$A$5:$A$1004,H24)) | R24: =IF(H24="","",SUMIFS(VENDAS!$K$5:$K$1004,VENDAS!$A$5:$A$1004,H24))
A25: =IF(A10="","",A10) | B25: =IF($A25="","",SUMIFS($M$5:$M$504,$J$5:$J$504,$A25,$S$5:$S$504,"Entregue")) | C25: =IF($A25="","",SUMIFS($N$5:$N$504,$J$5:$J$504,$A25,$S$5:$S$504,"Entregue")) | D25: =IF($A25="","",SUMIFS($O$5:$O$504,$J$5:$J$504,$A25,$S$5:$S$504,"Entregue")) | E25: =IF($A25="","",SUMIFS($P$5:$P$504,$J$5:$J$504,$A25,$S$5:$S$504,"Entregue")) | F25: =IF($A25="","",SUMIFS($R$5:$R$504,$J$5:$J$504,$A25,$S$5:$S$504,"Entregue")) | I25: =IF(H25="","",IFERROR(INDEX(VENDAS!$B$5:$B$1004,MATCH(H25,VENDAS!$A$5:$A$1004,0)),"não lançado")) | J25: =IF(H25="","",IFERROR(INDEX(VENDAS!$M$5:$M$1004,MATCH(H25,VENDAS!$A$5:$A$1004,0))&"","")) | K25: =IF(H25="","",IFERROR(INDEX(VENDAS!$J$5:$J$1004,MATCH(H25,VENDAS!$A$5:$A$1004,0))&"","")) | L25: =IF(H25="","",SUMIFS(VENDAS!$F$5:$F$1004,VENDAS!$A$5:$A$1004,H25)) | M25: =IF(H25="","",SUMIFS(VENDAS!$F$5:$F$1004,VENDAS!$A$5:$A$1004,H25,VENDAS!$D$5:$D$1004,M$4)) | N25: =IF(H25="","",SUMIFS(VENDAS!$F$5:$F$1004,VENDAS!$A$5:$A$1004,H25,VENDAS!$D$5:$D$1004,N$4)) | O25: =IF(H25="","",SUMIFS(VENDAS!$F$5:$F$1004,VENDAS!$A$5:$A$1004,H25,VENDAS!$D$5:$D$1004,O$4)) | P25: =IF(H25="","",SUMIFS(VENDAS!$F$5:$F$1004,VENDAS!$A$5:$A$1004,H25,VENDAS!$D$5:$D$1004,P$4)) | Q25: =IF(H25="","",SUMIFS(VENDAS!$H$5:$H$1004,VENDAS!$A$5:$A$1004,H25)) | R25: =IF(H25="","",SUMIFS(VENDAS!$K$5:$K$1004,VENDAS!$A$5:$A$1004,H25))
A26: =IF(A11="","",A11) | B26: =IF($A26="","",SUMIFS($M$5:$M$504,$J$5:$J$504,$A26,$S$5:$S$504,"Entregue")) | C26: =IF($A26="","",SUMIFS($N$5:$N$504,$J$5:$J$504,$A26,$S$5:$S$504,"Entregue")) | D26: =IF($A26="","",SUMIFS($O$5:$O$504,$J$5:$J$504,$A26,$S$5:$S$504,"Entregue")) | E26: =IF($A26="","",SUMIFS($P$5:$P$504,$J$5:$J$504,$A26,$S$5:$S$504,"Entregue")) | F26: =IF($A26="","",SUMIFS($R$5:$R$504,$J$5:$J$504,$A26,$S$5:$S$504,"Entregue")) | I26: =IF(H26="","",IFERROR(INDEX(VENDAS!$B$5:$B$1004,MATCH(H26,VENDAS!$A$5:$A$1004,0)),"não lançado")) | J26: =IF(H26="","",IFERROR(INDEX(VENDAS!$M$5:$M$1004,MATCH(H26,VENDAS!$A$5:$A$1004,0))&"","")) | K26: =IF(H26="","",IFERROR(INDEX(VENDAS!$J$5:$J$1004,MATCH(H26,VENDAS!$A$5:$A$1004,0))&"","")) | L26: =IF(H26="","",SUMIFS(VENDAS!$F$5:$F$1004,VENDAS!$A$5:$A$1004,H26)) | M26: =IF(H26="","",SUMIFS(VENDAS!$F$5:$F$1004,VENDAS!$A$5:$A$1004,H26,VENDAS!$D$5:$D$1004,M$4)) | N26: =IF(H26="","",SUMIFS(VENDAS!$F$5:$F$1004,VENDAS!$A$5:$A$1004,H26,VENDAS!$D$5:$D$1004,N$4)) | O26: =IF(H26="","",SUMIFS(VENDAS!$F$5:$F$1004,VENDAS!$A$5:$A$1004,H26,VENDAS!$D$5:$D$1004,O$4)) | P26: =IF(H26="","",SUMIFS(VENDAS!$F$5:$F$1004,VENDAS!$A$5:$A$1004,H26,VENDAS!$D$5:$D$1004,P$4)) | Q26: =IF(H26="","",SUMIFS(VENDAS!$H$5:$H$1004,VENDAS!$A$5:$A$1004,H26)) | R26: =IF(H26="","",SUMIFS(VENDAS!$K$5:$K$1004,VENDAS!$A$5:$A$1004,H26))
A27: =IF(A12="","",A12) | B27: =IF($A27="","",SUMIFS($M$5:$M$504,$J$5:$J$504,$A27,$S$5:$S$504,"Entregue")) | C27: =IF($A27="","",SUMIFS($N$5:$N$504,$J$5:$J$504,$A27,$S$5:$S$504,"Entregue")) | D27: =IF($A27="","",SUMIFS($O$5:$O$504,$J$5:$J$504,$A27,$S$5:$S$504,"Entregue")) | E27: =IF($A27="","",SUMIFS($P$5:$P$504,$J$5:$J$504,$A27,$S$5:$S$504,"Entregue")) | F27: =IF($A27="","",SUMIFS($R$5:$R$504,$J$5:$J$504,$A27,$S$5:$S$504,"Entregue")) | I27: =IF(H27="","",IFERROR(INDEX(VENDAS!$B$5:$B$1004,MATCH(H27,VENDAS!$A$5:$A$1004,0)),"não lançado")) | J27: =IF(H27="","",IFERROR(INDEX(VENDAS!$M$5:$M$1004,MATCH(H27,VENDAS!$A$5:$A$1004,0))&"","")) | K27: =IF(H27="","",IFERROR(INDEX(VENDAS!$J$5:$J$1004,MATCH(H27,VENDAS!$A$5:$A$1004,0))&"","")) | L27: =IF(H27="","",SUMIFS(VENDAS!$F$5:$F$1004,VENDAS!$A$5:$A$1004,H27)) | M27: =IF(H27="","",SUMIFS(VENDAS!$F$5:$F$1004,VENDAS!$A$5:$A$1004,H27,VENDAS!$D$5:$D$1004,M$4)) | N27: =IF(H27="","",SUMIFS(VENDAS!$F$5:$F$1004,VENDAS!$A$5:$A$1004,H27,VENDAS!$D$5:$D$1004,N$4)) | O27: =IF(H27="","",SUMIFS(VENDAS!$F$5:$F$1004,VENDAS!$A$5:$A$1004,H27,VENDAS!$D$5:$D$1004,O$4)) | P27: =IF(H27="","",SUMIFS(VENDAS!$F$5:$F$1004,VENDAS!$A$5:$A$1004,H27,VENDAS!$D$5:$D$1004,P$4)) | Q27: =IF(H27="","",SUMIFS(VENDAS!$H$5:$H$1004,VENDAS!$A$5:$A$1004,H27)) | R27: =IF(H27="","",SUMIFS(VENDAS!$K$5:$K$1004,VENDAS!$A$5:$A$1004,H27))
A28: =IF(A13="","",A13) | B28: =IF($A28="","",SUMIFS($M$5:$M$504,$J$5:$J$504,$A28,$S$5:$S$504,"Entregue")) | C28: =IF($A28="","",SUMIFS($N$5:$N$504,$J$5:$J$504,$A28,$S$5:$S$504,"Entregue")) | D28: =IF($A28="","",SUMIFS($O$5:$O$504,$J$5:$J$504,$A28,$S$5:$S$504,"Entregue")) | E28: =IF($A28="","",SUMIFS($P$5:$P$504,$J$5:$J$504,$A28,$S$5:$S$504,"Entregue")) | F28: =IF($A28="","",SUMIFS($R$5:$R$504,$J$5:$J$504,$A28,$S$5:$S$504,"Entregue")) | I28: =IF(H28="","",IFERROR(INDEX(VENDAS!$B$5:$B$1004,MATCH(H28,VENDAS!$A$5:$A$1004,0)),"não lançado")) | J28: =IF(H28="","",IFERROR(INDEX(VENDAS!$M$5:$M$1004,MATCH(H28,VENDAS!$A$5:$A$1004,0))&"","")) | K28: =IF(H28="","",IFERROR(INDEX(VENDAS!$J$5:$J$1004,MATCH(H28,VENDAS!$A$5:$A$1004,0))&"","")) | L28: =IF(H28="","",SUMIFS(VENDAS!$F$5:$F$1004,VENDAS!$A$5:$A$1004,H28)) | M28: =IF(H28="","",SUMIFS(VENDAS!$F$5:$F$1004,VENDAS!$A$5:$A$1004,H28,VENDAS!$D$5:$D$1004,M$4)) | N28: =IF(H28="","",SUMIFS(VENDAS!$F$5:$F$1004,VENDAS!$A$5:$A$1004,H28,VENDAS!$D$5:$D$1004,N$4)) | O28: =IF(H28="","",SUMIFS(VENDAS!$F$5:$F$1004,VENDAS!$A$5:$A$1004,H28,VENDAS!$D$5:$D$1004,O$4)) | P28: =IF(H28="","",SUMIFS(VENDAS!$F$5:$F$1004,VENDAS!$A$5:$A$1004,H28,VENDAS!$D$5:$D$1004,P$4)) | Q28: =IF(H28="","",SUMIFS(VENDAS!$H$5:$H$1004,VENDAS!$A$5:$A$1004,H28)) | R28: =IF(H28="","",SUMIFS(VENDAS!$K$5:$K$1004,VENDAS!$A$5:$A$1004,H28))
A29: =IF(A14="","",A14) | B29: =IF($A29="","",SUMIFS($M$5:$M$504,$J$5:$J$504,$A29,$S$5:$S$504,"Entregue")) | C29: =IF($A29="","",SUMIFS($N$5:$N$504,$J$5:$J$504,$A29,$S$5:$S$504,"Entregue")) | D29: =IF($A29="","",SUMIFS($O$5:$O$504,$J$5:$J$504,$A29,$S$5:$S$504,"Entregue")) | E29: =IF($A29="","",SUMIFS($P$5:$P$504,$J$5:$J$504,$A29,$S$5:$S$504,"Entregue")) | F29: =IF($A29="","",SUMIFS($R$5:$R$504,$J$5:$J$504,$A29,$S$5:$S$504,"Entregue")) | I29: =IF(H29="","",IFERROR(INDEX(VENDAS!$B$5:$B$1004,MATCH(H29,VENDAS!$A$5:$A$1004,0)),"não lançado")) | J29: =IF(H29="","",IFERROR(INDEX(VENDAS!$M$5:$M$1004,MATCH(H29,VENDAS!$A$5:$A$1004,0))&"","")) | K29: =IF(H29="","",IFERROR(INDEX(VENDAS!$J$5:$J$1004,MATCH(H29,VENDAS!$A$5:$A$1004,0))&"","")) | L29: =IF(H29="","",SUMIFS(VENDAS!$F$5:$F$1004,VENDAS!$A$5:$A$1004,H29)) | M29: =IF(H29="","",SUMIFS(VENDAS!$F$5:$F$1004,VENDAS!$A$5:$A$1004,H29,VENDAS!$D$5:$D$1004,M$4)) | N29: =IF(H29="","",SUMIFS(VENDAS!$F$5:$F$1004,VENDAS!$A$5:$A$1004,H29,VENDAS!$D$5:$D$1004,N$4)) | O29: =IF(H29="","",SUMIFS(VENDAS!$F$5:$F$1004,VENDAS!$A$5:$A$1004,H29,VENDAS!$D$5:$D$1004,O$4)) | P29: =IF(H29="","",SUMIFS(VENDAS!$F$5:$F$1004,VENDAS!$A$5:$A$1004,H29,VENDAS!$D$5:$D$1004,P$4)) | Q29: =IF(H29="","",SUMIFS(VENDAS!$H$5:$H$1004,VENDAS!$A$5:$A$1004,H29)) | R29: =IF(H29="","",SUMIFS(VENDAS!$K$5:$K$1004,VENDAS!$A$5:$A$1004,H29))
I30: =IF(H30="","",IFERROR(INDEX(VENDAS!$B$5:$B$1004,MATCH(H30,VENDAS!$A$5:$A$1004,0)),"não lançado")) | J30: =IF(H30="","",IFERROR(INDEX(VENDAS!$M$5:$M$1004,MATCH(H30,VENDAS!$A$5:$A$1004,0))&"","")) | K30: =IF(H30="","",IFERROR(INDEX(VENDAS!$J$5:$J$1004,MATCH(H30,VENDAS!$A$5:$A$1004,0))&"","")) | L30: =IF(H30="","",SUMIFS(VENDAS!$F$5:$F$1004,VENDAS!$A$5:$A$1004,H30)) | M30: =IF(H30="","",SUMIFS(VENDAS!$F$5:$F$1004,VENDAS!$A$5:$A$1004,H30,VENDAS!$D$5:$D$1004,M$4)) | N30: =IF(H30="","",SUMIFS(VENDAS!$F$5:$F$1004,VENDAS!$A$5:$A$1004,H30,VENDAS!$D$5:$D$1004,N$4)) | O30: =IF(H30="","",SUMIFS(VENDAS!$F$5:$F$1004,VENDAS!$A$5:$A$1004,H30,VENDAS!$D$5:$D$1004,O$4)) | P30: =IF(H30="","",SUMIFS(VENDAS!$F$5:$F$1004,VENDAS!$A$5:$A$1004,H30,VENDAS!$D$5:$D$1004,P$4)) | Q30: =IF(H30="","",SUMIFS(VENDAS!$H$5:$H$1004,VENDAS!$A$5:$A$1004,H30)) | R30: =IF(H30="","",SUMIFS(VENDAS!$K$5:$K$1004,VENDAS!$A$5:$A$1004,H30))
A31: Taxas = soma das taxas de entrega dos pedidos com status 'Entregue' (base para o repasse ao motoboy). | I31: =IF(H31="","",IFERROR(INDEX(VENDAS!$B$5:$B$1004,MATCH(H31,VENDAS!$A$5:$A$1004,0)),"não lançado")) | J31: =IF(H31="","",IFERROR(INDEX(VENDAS!$M$5:$M$1004,MATCH(H31,VENDAS!$A$5:$A$1004,0))&"","")) | K31: =IF(H31="","",IFERROR(INDEX(VENDAS!$J$5:$J$1004,MATCH(H31,VENDAS!$A$5:$A$1004,0))&"","")) | L31: =IF(H31="","",SUMIFS(VENDAS!$F$5:$F$1004,VENDAS!$A$5:$A$1004,H31)) | M31: =IF(H31="","",SUMIFS(VENDAS!$F$5:$F$1004,VENDAS!$A$5:$A$1004,H31,VENDAS!$D$5:$D$1004,M$4)) | N31: =IF(H31="","",SUMIFS(VENDAS!$F$5:$F$1004,VENDAS!$A$5:$A$1004,H31,VENDAS!$D$5:$D$1004,N$4)) | O31: =IF(H31="","",SUMIFS(VENDAS!$F$5:$F$1004,VENDAS!$A$5:$A$1004,H31,VENDAS!$D$5:$D$1004,O$4)) | P31: =IF(H31="","",SUMIFS(VENDAS!$F$5:$F$1004,VENDAS!$A$5:$A$1004,H31,VENDAS!$D$5:$D$1004,P$4)) | Q31: =IF(H31="","",SUMIFS(VENDAS!$H$5:$H$1004,VENDAS!$A$5:$A$1004,H31)) | R31: =IF(H31="","",SUMIFS(VENDAS!$K$5:$K$1004,VENDAS!$A$5:$A$1004,H31))
I32: =IF(H32="","",IFERROR(INDEX(VENDAS!$B$5:$B$1004,MATCH(H32,VENDAS!$A$5:$A$1004,0)),"não lançado")) | J32: =IF(H32="","",IFERROR(INDEX(VENDAS!$M$5:$M$1004,MATCH(H32,VENDAS!$A$5:$A$1004,0))&"","")) | K32: =IF(H32="","",IFERROR(INDEX(VENDAS!$J$5:$J$1004,MATCH(H32,VENDAS!$A$5:$A$1004,0))&"","")) | L32: =IF(H32="","",SUMIFS(VENDAS!$F$5:$F$1004,VENDAS!$A$5:$A$1004,H32)) | M32: =IF(H32="","",SUMIFS(VENDAS!$F$5:$F$1004,VENDAS!$A$5:$A$1004,H32,VENDAS!$D$5:$D$1004,M$4)) | N32: =IF(H32="","",SUMIFS(VENDAS!$F$5:$F$1004,VENDAS!$A$5:$A$1004,H32,VENDAS!$D$5:$D$1004,N$4)) | O32: =IF(H32="","",SUMIFS(VENDAS!$F$5:$F$1004,VENDAS!$A$5:$A$1004,H32,VENDAS!$D$5:$D$1004,O$4)) | P32: =IF(H32="","",SUMIFS(VENDAS!$F$5:$F$1004,VENDAS!$A$5:$A$1004,H32,VENDAS!$D$5:$D$1004,P$4)) | Q32: =IF(H32="","",SUMIFS(VENDAS!$H$5:$H$1004,VENDAS!$A$5:$A$1004,H32)) | R32: =IF(H32="","",SUMIFS(VENDAS!$K$5:$K$1004,VENDAS!$A$5:$A$1004,H32))
I33: =IF(H33="","",IFERROR(INDEX(VENDAS!$B$5:$B$1004,MATCH(H33,VENDAS!$A$5:$A$1004,0)),"não lançado")) | J33: =IF(H33="","",IFERROR(INDEX(VENDAS!$M$5:$M$1004,MATCH(H33,VENDAS!$A$5:$A$1004,0))&"","")) | K33: =IF(H33="","",IFERROR(INDEX(VENDAS!$J$5:$J$1004,MATCH(H33,VENDAS!$A$5:$A$1004,0))&"","")) | L33: =IF(H33="","",SUMIFS(VENDAS!$F$5:$F$1004,VENDAS!$A$5:$A$1004,H33)) | M33: =IF(H33="","",SUMIFS(VENDAS!$F$5:$F$1004,VENDAS!$A$5:$A$1004,H33,VENDAS!$D$5:$D$1004,M$4)) | N33: =IF(H33="","",SUMIFS(VENDAS!$F$5:$F$1004,VENDAS!$A$5:$A$1004,H33,VENDAS!$D$5:$D$1004,N$4)) | O33: =IF(H33="","",SUMIFS(VENDAS!$F$5:$F$1004,VENDAS!$A$5:$A$1004,H33,VENDAS!$D$5:$D$1004,O$4)) | P33: =IF(H33="","",SUMIFS(VENDAS!$F$5:$F$1004,VENDAS!$A$5:$A$1004,H33,VENDAS!$D$5:$D$1004,P$4)) | Q33: =IF(H33="","",SUMIFS(VENDAS!$H$5:$H$1004,VENDAS!$A$5:$A$1004,H33)) | R33: =IF(H33="","",SUMIFS(VENDAS!$K$5:$K$1004,VENDAS!$A$5:$A$1004,H33))
I34: =IF(H34="","",IFERROR(INDEX(VENDAS!$B$5:$B$1004,MATCH(H34,VENDAS!$A$5:$A$1004,0)),"não lançado")) | J34: =IF(H34="","",IFERROR(INDEX(VENDAS!$M$5:$M$1004,MATCH(H34,VENDAS!$A$5:$A$1004,0))&"","")) | K34: =IF(H34="","",IFERROR(INDEX(VENDAS!$J$5:$J$1004,MATCH(H34,VENDAS!$A$5:$A$1004,0))&"","")) | L34: =IF(H34="","",SUMIFS(VENDAS!$F$5:$F$1004,VENDAS!$A$5:$A$1004,H34)) | M34: =IF(H34="","",SUMIFS(VENDAS!$F$5:$F$1004,VENDAS!$A$5:$A$1004,H34,VENDAS!$D$5:$D$1004,M$4)) | N34: =IF(H34="","",SUMIFS(VENDAS!$F$5:$F$1004,VENDAS!$A$5:$A$1004,H34,VENDAS!$D$5:$D$1004,N$4)) | O34: =IF(H34="","",SUMIFS(VENDAS!$F$5:$F$1004,VENDAS!$A$5:$A$1004,H34,VENDAS!$D$5:$D$1004,O$4)) | P34: =IF(H34="","",SUMIFS(VENDAS!$F$5:$F$1004,VENDAS!$A$5:$A$1004,H34,VENDAS!$D$5:$D$1004,P$4)) | Q34: =IF(H34="","",SUMIFS(VENDAS!$H$5:$H$1004,VENDAS!$A$5:$A$1004,H34)) | R34: =IF(H34="","",SUMIFS(VENDAS!$K$5:$K$1004,VENDAS!$A$5:$A$1004,H34))
I35: =IF(H35="","",IFERROR(INDEX(VENDAS!$B$5:$B$1004,MATCH(H35,VENDAS!$A$5:$A$1004,0)),"não lançado")) | J35: =IF(H35="","",IFERROR(INDEX(VENDAS!$M$5:$M$1004,MATCH(H35,VENDAS!$A$5:$A$1004,0))&"","")) | K35: =IF(H35="","",IFERROR(INDEX(VENDAS!$J$5:$J$1004,MATCH(H35,VENDAS!$A$5:$A$1004,0))&"","")) | L35: =IF(H35="","",SUMIFS(VENDAS!$F$5:$F$1004,VENDAS!$A$5:$A$1004,H35)) | M35: =IF(H35="","",SUMIFS(VENDAS!$F$5:$F$1004,VENDAS!$A$5:$A$1004,H35,VENDAS!$D$5:$D$1004,M$4)) | N35: =IF(H35="","",SUMIFS(VENDAS!$F$5:$F$1004,VENDAS!$A$5:$A$1004,H35,VENDAS!$D$5:$D$1004,N$4)) | O35: =IF(H35="","",SUMIFS(VENDAS!$F$5:$F$1004,VENDAS!$A$5:$A$1004,H35,VENDAS!$D$5:$D$1004,O$4)) | P35: =IF(H35="","",SUMIFS(VENDAS!$F$5:$F$1004,VENDAS!$A$5:$A$1004,H35,VENDAS!$D$5:$D$1004,P$4)) | Q35: =IF(H35="","",SUMIFS(VENDAS!$H$5:$H$1004,VENDAS!$A$5:$A$1004,H35)) | R35: =IF(H35="","",SUMIFS(VENDAS!$K$5:$K$1004,VENDAS!$A$5:$A$1004,H35))
I36: =IF(H36="","",IFERROR(INDEX(VENDAS!$B$5:$B$1004,MATCH(H36,VENDAS!$A$5:$A$1004,0)),"não lançado")) | J36: =IF(H36="","",IFERROR(INDEX(VENDAS!$M$5:$M$1004,MATCH(H36,VENDAS!$A$5:$A$1004,0))&"","")) | K36: =IF(H36="","",IFERROR(INDEX(VENDAS!$J$5:$J$1004,MATCH(H36,VENDAS!$A$5:$A$1004,0))&"","")) | L36: =IF(H36="","",SUMIFS(VENDAS!$F$5:$F$1004,VENDAS!$A$5:$A$1004,H36)) | M36: =IF(H36="","",SUMIFS(VENDAS!$F$5:$F$1004,VENDAS!$A$5:$A$1004,H36,VENDAS!$D$5:$D$1004,M$4)) | N36: =IF(H36="","",SUMIFS(VENDAS!$F$5:$F$1004,VENDAS!$A$5:$A$1004,H36,VENDAS!$D$5:$D$1004,N$4)) | O36: =IF(H36="","",SUMIFS(VENDAS!$F$5:$F$1004,VENDAS!$A$5:$A$1004,H36,VENDAS!$D$5:$D$1004,O$4)) | P36: =IF(H36="","",SUMIFS(VENDAS!$F$5:$F$1004,VENDAS!$A$5:$A$1004,H36,VENDAS!$D$5:$D$1004,P$4)) | Q36: =IF(H36="","",SUMIFS(VENDAS!$H$5:$H$1004,VENDAS!$A$5:$A$1004,H36)) | R36: =IF(H36="","",SUMIFS(VENDAS!$K$5:$K$1004,VENDAS!$A$5:$A$1004,H36))
I37: =IF(H37="","",IFERROR(INDEX(VENDAS!$B$5:$B$1004,MATCH(H37,VENDAS!$A$5:$A$1004,0)),"não lançado")) | J37: =IF(H37="","",IFERROR(INDEX(VENDAS!$M$5:$M$1004,MATCH(H37,VENDAS!$A$5:$A$1004,0))&"","")) | K37: =IF(H37="","",IFERROR(INDEX(VENDAS!$J$5:$J$1004,MATCH(H37,VENDAS!$A$5:$A$1004,0))&"","")) | L37: =IF(H37="","",SUMIFS(VENDAS!$F$5:$F$1004,VENDAS!$A$5:$A$1004,H37)) | M37: =IF(H37="","",SUMIFS(VENDAS!$F$5:$F$1004,VENDAS!$A$5:$A$1004,H37,VENDAS!$D$5:$D$1004,M$4)) | N37: =IF(H37="","",SUMIFS(VENDAS!$F$5:$F$1004,VENDAS!$A$5:$A$1004,H37,VENDAS!$D$5:$D$1004,N$4)) | O37: =IF(H37="","",SUMIFS(VENDAS!$F$5:$F$1004,VENDAS!$A$5:$A$1004,H37,VENDAS!$D$5:$D$1004,O$4)) | P37: =IF(H37="","",SUMIFS(VENDAS!$F$5:$F$1004,VENDAS!$A$5:$A$1004,H37,VENDAS!$D$5:$D$1004,P$4)) | Q37: =IF(H37="","",SUMIFS(VENDAS!$H$5:$H$1004,VENDAS!$A$5:$A$1004,H37)) | R37: =IF(H37="","",SUMIFS(VENDAS!$K$5:$K$1004,VENDAS!$A$5:$A$1004,H37))
I38: =IF(H38="","",IFERROR(INDEX(VENDAS!$B$5:$B$1004,MATCH(H38,VENDAS!$A$5:$A$1004,0)),"não lançado")) | J38: =IF(H38="","",IFERROR(INDEX(VENDAS!$M$5:$M$1004,MATCH(H38,VENDAS!$A$5:$A$1004,0))&"","")) | K38: =IF(H38="","",IFERROR(INDEX(VENDAS!$J$5:$J$1004,MATCH(H38,VENDAS!$A$5:$A$1004,0))&"","")) | L38: =IF(H38="","",SUMIFS(VENDAS!$F$5:$F$1004,VENDAS!$A$5:$A$1004,H38)) | M38: =IF(H38="","",SUMIFS(VENDAS!$F$5:$F$1004,VENDAS!$A$5:$A$1004,H38,VENDAS!$D$5:$D$1004,M$4)) | N38: =IF(H38="","",SUMIFS(VENDAS!$F$5:$F$1004,VENDAS!$A$5:$A$1004,H38,VENDAS!$D$5:$D$1004,N$4)) | O38: =IF(H38="","",SUMIFS(VENDAS!$F$5:$F$1004,VENDAS!$A$5:$A$1004,H38,VENDAS!$D$5:$D$1004,O$4)) | P38: =IF(H38="","",SUMIFS(VENDAS!$F$5:$F$1004,VENDAS!$A$5:$A$1004,H38,VENDAS!$D$5:$D$1004,P$4)) | Q38: =IF(H38="","",SUMIFS(VENDAS!$H$5:$H$1004,VENDAS!$A$5:$A$1004,H38)) | R38: =IF(H38="","",SUMIFS(VENDAS!$K$5:$K$1004,VENDAS!$A$5:$A$1004,H38))
I39: =IF(H39="","",IFERROR(INDEX(VENDAS!$B$5:$B$1004,MATCH(H39,VENDAS!$A$5:$A$1004,0)),"não lançado")) | J39: =IF(H39="","",IFERROR(INDEX(VENDAS!$M$5:$M$1004,MATCH(H39,VENDAS!$A$5:$A$1004,0))&"","")) | K39: =IF(H39="","",IFERROR(INDEX(VENDAS!$J$5:$J$1004,MATCH(H39,VENDAS!$A$5:$A$1004,0))&"","")) | L39: =IF(H39="","",SUMIFS(VENDAS!$F$5:$F$1004,VENDAS!$A$5:$A$1004,H39)) | M39: =IF(H39="","",SUMIFS(VENDAS!$F$5:$F$1004,VENDAS!$A$5:$A$1004,H39,VENDAS!$D$5:$D$1004,M$4)) | N39: =IF(H39="","",SUMIFS(VENDAS!$F$5:$F$1004,VENDAS!$A$5:$A$1004,H39,VENDAS!$D$5:$D$1004,N$4)) | O39: =IF(H39="","",SUMIFS(VENDAS!$F$5:$F$1004,VENDAS!$A$5:$A$1004,H39,VENDAS!$D$5:$D$1004,O$4)) | P39: =IF(H39="","",SUMIFS(VENDAS!$F$5:$F$1004,VENDAS!$A$5:$A$1004,H39,VENDAS!$D$5:$D$1004,P$4)) | Q39: =IF(H39="","",SUMIFS(VENDAS!$H$5:$H$1004,VENDAS!$A$5:$A$1004,H39)) | R39: =IF(H39="","",SUMIFS(VENDAS!$K$5:$K$1004,VENDAS!$A$5:$A$1004,H39))
I40: =IF(H40="","",IFERROR(INDEX(VENDAS!$B$5:$B$1004,MATCH(H40,VENDAS!$A$5:$A$1004,0)),"não lançado")) | J40: =IF(H40="","",IFERROR(INDEX(VENDAS!$M$5:$M$1004,MATCH(H40,VENDAS!$A$5:$A$1004,0))&"","")) | K40: =IF(H40="","",IFERROR(INDEX(VENDAS!$J$5:$J$1004,MATCH(H40,VENDAS!$A$5:$A$1004,0))&"","")) | L40: =IF(H40="","",SUMIFS(VENDAS!$F$5:$F$1004,VENDAS!$A$5:$A$1004,H40)) | M40: =IF(H40="","",SUMIFS(VENDAS!$F$5:$F$1004,VENDAS!$A$5:$A$1004,H40,VENDAS!$D$5:$D$1004,M$4)) | N40: =IF(H40="","",SUMIFS(VENDAS!$F$5:$F$1004,VENDAS!$A$5:$A$1004,H40,VENDAS!$D$5:$D$1004,N$4)) | O40: =IF(H40="","",SUMIFS(VENDAS!$F$5:$F$1004,VENDAS!$A$5:$A$1004,H40,VENDAS!$D$5:$D$1004,O$4)) | P40: =IF(H40="","",SUMIFS(VENDAS!$F$5:$F$1004,VENDAS!$A$5:$A$1004,H40,VENDAS!$D$5:$D$1004,P$4)) | Q40: =IF(H40="","",SUMIFS(VENDAS!$H$5:$H$1004,VENDAS!$A$5:$A$1004,H40)) | R40: =IF(H40="","",SUMIFS(VENDAS!$K$5:$K$1004,VENDAS!$A$5:$A$1004,H40))
I41: =IF(H41="","",IFERROR(INDEX(VENDAS!$B$5:$B$1004,MATCH(H41,VENDAS!$A$5:$A$1004,0)),"não lançado")) | J41: =IF(H41="","",IFERROR(INDEX(VENDAS!$M$5:$M$1004,MATCH(H41,VENDAS!$A$5:$A$1004,0))&"","")) | K41: =IF(H41="","",IFERROR(INDEX(VENDAS!$J$5:$J$1004,MATCH(H41,VENDAS!$A$5:$A$1004,0))&"","")) | L41: =IF(H41="","",SUMIFS(VENDAS!$F$5:$F$1004,VENDAS!$A$5:$A$1004,H41)) | M41: =IF(H41="","",SUMIFS(VENDAS!$F$5:$F$1004,VENDAS!$A$5:$A$1004,H41,VENDAS!$D$5:$D$1004,M$4)) | N41: =IF(H41="","",SUMIFS(VENDAS!$F$5:$F$1004,VENDAS!$A$5:$A$1004,H41,VENDAS!$D$5:$D$1004,N$4)) | O41: =IF(H41="","",SUMIFS(VENDAS!$F$5:$F$1004,VENDAS!$A$5:$A$1004,H41,VENDAS!$D$5:$D$1004,O$4)) | P41: =IF(H41="","",SUMIFS(VENDAS!$F$5:$F$1004,VENDAS!$A$5:$A$1004,H41,VENDAS!$D$5:$D$1004,P$4)) | Q41: =IF(H41="","",SUMIFS(VENDAS!$H$5:$H$1004,VENDAS!$A$5:$A$1004,H41)) | R41: =IF(H41="","",SUMIFS(VENDAS!$K$5:$K$1004,VENDAS!$A$5:$A$1004,H41))
...

Sheet MAPA
A1: MAPA — Entregas em Palmas – TO
A2: Taxa por quadra/bairro e desempenho de cada região
A4: Região de entrega | B4: Tipo | C4: Taxa de entrega (R$) | D4: Pedidos | E4: Unidades | F4: Vendas em produtos (R$) | G4: Taxas recebidas (R$) | H4: % dos pedidos
A5: Quadras 700 Sul a 200 Norte/Sul | B5: Quadras | C5: 8 | D5: =SUMIFS(VENDAS!$O$5:$O$1004,VENDAS!$J$5:$J$1004,A5) | E5: =SUMIFS(VENDAS!$F$5:$F$1004,VENDAS!$J$5:$J$1004,A5) | F5: =SUMIFS(VENDAS!$H$5:$H$1004,VENDAS!$J$5:$J$1004,A5) | G5: =SUMIFS(VENDAS!$K$5:$K$1004,VENDAS!$J$5:$J$1004,A5) | H5: =IF($D$15=0,0,D5/$D$15)
A6: Quadras 300 Norte a 600 Norte | B6: Quadras | C6: 10 | D6: =SUMIFS(VENDAS!$O$5:$O$1004,VENDAS!$J$5:$J$1004,A6) | E6: =SUMIFS(VENDAS!$F$5:$F$1004,VENDAS!$J$5:$J$1004,A6) | F6: =SUMIFS(VENDAS!$H$5:$H$1004,VENDAS!$J$5:$J$1004,A6) | G6: =SUMIFS(VENDAS!$K$5:$K$1004,VENDAS!$J$5:$J$1004,A6) | H6: =IF($D$15=0,0,D6/$D$15)
A7: Quadras 800 a 1200 | B7: Quadras | C7: 10 | D7: =SUMIFS(VENDAS!$O$5:$O$1004,VENDAS!$J$5:$J$1004,A7) | E7: =SUMIFS(VENDAS!$F$5:$F$1004,VENDAS!$J$5:$J$1004,A7) | F7: =SUMIFS(VENDAS!$H$5:$H$1004,VENDAS!$J$5:$J$1004,A7) | G7: =SUMIFS(VENDAS!$K$5:$K$1004,VENDAS!$J$5:$J$1004,A7) | H7: =IF($D$15=0,0,D7/$D$15)
A8: Quadras 1300 a 1500 Sul | B8: Quadras | C8: 15 | D8: =SUMIFS(VENDAS!$O$5:$O$1004,VENDAS!$J$5:$J$1004,A8) | E8: =SUMIFS(VENDAS!$F$5:$F$1004,VENDAS!$J$5:$J$1004,A8) | F8: =SUMIFS(VENDAS!$H$5:$H$1004,VENDAS!$J$5:$J$1004,A8) | G8: =SUMIFS(VENDAS!$K$5:$K$1004,VENDAS!$J$5:$J$1004,A8) | H8: =IF($D$15=0,0,D8/$D$15)
A9: Santo Amaro | B9: Bairro | C9: 15 | D9: =SUMIFS(VENDAS!$O$5:$O$1004,VENDAS!$J$5:$J$1004,A9) | E9: =SUMIFS(VENDAS!$F$5:$F$1004,VENDAS!$J$5:$J$1004,A9) | F9: =SUMIFS(VENDAS!$H$5:$H$1004,VENDAS!$J$5:$J$1004,A9) | G9: =SUMIFS(VENDAS!$K$5:$K$1004,VENDAS!$J$5:$J$1004,A9) | H9: =IF($D$15=0,0,D9/$D$15)
A10: Lago Norte | B10: Bairro | C10: 20 | D10: =SUMIFS(VENDAS!$O$5:$O$1004,VENDAS!$J$5:$J$1004,A10) | E10: =SUMIFS(VENDAS!$F$5:$F$1004,VENDAS!$J$5:$J$1004,A10) | F10: =SUMIFS(VENDAS!$H$5:$H$1004,VENDAS!$J$5:$J$1004,A10) | G10: =SUMIFS(VENDAS!$K$5:$K$1004,VENDAS!$J$5:$J$1004,A10) | H10: =IF($D$15=0,0,D10/$D$15)
A11: Bertaville e Aurenys | B11: Bairro | C11: 30 | D11: =SUMIFS(VENDAS!$O$5:$O$1004,VENDAS!$J$5:$J$1004,A11) | E11: =SUMIFS(VENDAS!$F$5:$F$1004,VENDAS!$J$5:$J$1004,A11) | F11: =SUMIFS(VENDAS!$H$5:$H$1004,VENDAS!$J$5:$J$1004,A11) | G11: =SUMIFS(VENDAS!$K$5:$K$1004,VENDAS!$J$5:$J$1004,A11) | H11: =IF($D$15=0,0,D11/$D$15)
A12: Taquaralto e Lago Sul | B12: Bairro | C12: 35 | D12: =SUMIFS(VENDAS!$O$5:$O$1004,VENDAS!$J$5:$J$1004,A12) | E12: =SUMIFS(VENDAS!$F$5:$F$1004,VENDAS!$J$5:$J$1004,A12) | F12: =SUMIFS(VENDAS!$H$5:$H$1004,VENDAS!$J$5:$J$1004,A12) | G12: =SUMIFS(VENDAS!$K$5:$K$1004,VENDAS!$J$5:$J$1004,A12) | H12: =IF($D$15=0,0,D12/$D$15)
A13: Taquari | B13: Bairro | C13: 35 | D13: =SUMIFS(VENDAS!$O$5:$O$1004,VENDAS!$J$5:$J$1004,A13) | E13: =SUMIFS(VENDAS!$F$5:$F$1004,VENDAS!$J$5:$J$1004,A13) | F13: =SUMIFS(VENDAS!$H$5:$H$1004,VENDAS!$J$5:$J$1004,A13) | G13: =SUMIFS(VENDAS!$K$5:$K$1004,VENDAS!$J$5:$J$1004,A13) | H13: =IF($D$15=0,0,D13/$D$15)
A14: Retirada / sem entrega | B14: Outro | C14: 0 | D14: =SUMIFS(VENDAS!$O$5:$O$1004,VENDAS!$J$5:$J$1004,A14) | E14: =SUMIFS(VENDAS!$F$5:$F$1004,VENDAS!$J$5:$J$1004,A14) | F14: =SUMIFS(VENDAS!$H$5:$H$1004,VENDAS!$J$5:$J$1004,A14) | G14: =SUMIFS(VENDAS!$K$5:$K$1004,VENDAS!$J$5:$J$1004,A14) | H14: =IF($D$15=0,0,D14/$D$15)
A15: TOTAL | D15: =SUM(D5:D14) | E15: =SUM(E5:E14) | F15: =SUM(F5:F14) | G15: =SUM(G5:G14) | H15: =SUM(H5:H14)
A17: Legenda das quadras (Plano Diretor de Palmas):
A18: • 700 Sul a 200 Norte/Sul — região central (Praça dos Girassóis e entorno).
A19: • 300 a 600 Norte — Plano Diretor Norte.
A20: • 800 a 1200 — Plano Diretor Sul intermediário.
A21: • 1300 a 1500 Sul — extremo sul do Plano Diretor.
A22: • Bairros fora do Plano Diretor: Santo Amaro, Lago Norte, Bertaville, Aurenys, Taquaralto, Lago Sul, Taquari.
A23: • Região fora da lista: combinar a taxa no WhatsApp e lançar como 'Retirada / sem entrega' + ajustar a taxa.
